Workbook

Sheet SalvageEntry
H1: Holding Cells - wait until these are clear before submitting another set of data
A2: Waste to landfill | B2: Date (DD-MM) | C2: 46303 | D2: Enter a value in every box
B3: Weight Up (kg) | D3: Do not press submit unless all boxes are green
B4: Iron and steel | C4: 0
A5: Materials Up (%) | B5: Timber | C5: 0
B6: Textiles | C6: 0
B7: Plastics | C7: 0
B8: Paper and cardboard | C8: 0
B9: Mattresses | C9: 0
B10: Ewaste | C10: 0
B11: Glass | C11: 0
B12: Mixed materials | C12: 0
C13: =SUM(C4:C12) -> 0 | D13: <----Total. Do not press submit unless this is 100
G15: <---- If 100% mixed - enter the date and weight,
G16: then press this button for speedier results
A18: Salvage from landfill | B18: Date (DD-MM) | C18: =C2 -> 46303 | D18: Enter a value in every box
B19: Weight Down (kg) | D19: Do not press submit unless all boxes are green
A20: Materials Down | B20: Iron and steel | C20: 0
B21: Aluminium | C21: 0
B22: Other non-ferrous | C22: 0
B23: Mixed metals | C23: 0
B24: Ewaste | C24: 0
B25: Lead acid batteries | C25: 0
B26: Timber | C26: 0
B27: Bricks | C27: 0
B28: Building and demolition | C28: 0
B29: Whitegoods | C29: 0
B30: Paper and cardboard | C30: 0
B31: Plastics | C31: 0
B32: Glass | C32: 0
B33: Mixed materials | C33: 0
C34: =SUM(C20:C33) -> 0 | D34: <----Total. Do not press submit unless this is 100 | H34: =SUM(H20:H33) -> 0
G36: <---- If 100% mixed - enter the date and weight,
G37: then press this button for speedier results

Sheet ContainerEntry
H1: Holding Cells - wait until these are clear before submitting another set of data
B2: Date (DD-MM) | C2: 46302 | D2: Enter a value in every box
B3: Container Type | C3: 5
B4: Weight
B5: Iron and steel | C5: 0 | D5: Do not press submit unless all boxes are green
B6: Aluminium | C6: 0
B7: Other non-ferrous | C7: 0
B8: Mixed metals | C8: 0 | L8: Container Type
B9: Textiles | C9: 0 | K9: Apple crate | L9: 1
B10: Mattresses | C10: 0 | K10: Plastic pallet | L10: 2
B11: Timber | C11: 0 | K11: Pine pallet | L11: 3
B12: Bricks | C12: 0 | K12: Hardwood pallet | L12: 4
B13: Building and demolition | C13: 0 | K13: Collectable Tub | L13: 5
B14: Paper and cardboard | C14: 0 | K14: Pickup | L14: 6
B15: Plastics | C15: 0
B16: Glass | C16: 0
B17: Mixed materials | C17: 0
C18: =SUM(C5:C17) -> 0 | D18: <----Total. Do not press submit unless this is 100
B28: Pallet and crate tare weights: do not change these numbers
B29: Crate | C29: 60
B30: Plastic Pallet | C30: 6
B31: Pine Pallet | C31: 18
B32: Hardwood Pallet | C32: 30

Sheet ElecEntry
H1: Holding Cells - wait until these are clear before submitting another set of data
B2: Date (DD-MM) | C2: 46316 | D2: Enter a value in every box | Z2: -
B3: Container Type
B4: Weight
B5: TVs, Monitors, Proj | C5: 0 | D5: Do not press submit unless all boxes are green
B6: Everything Else | C6: 0
C7: =SUM(C5:C6) -> 0 | D7: <----Total. Do not press submit unless this is 100
G14: <---- If 100% mixed - just enter the date,
G15: then press the relevant button for speedier results
B17: Pallet and crate tare weights: do not change these numbers
B18: Stillage Cage | C18: 50
B19: Plastic Pallet | C19: 6
B20: Pine Pallet | C20: 18
B21: Hardwood Pallet | C21: 30

Sheet SalvageUpList
B1: Date | C1: Weight Up | D1: Iron and steel | E1: Timber | F1: Textiles | G1: Plastics | H1: Paper and cardboard | I1: Mattresses | J1: Ewaste | K1: Glass | L1: Mixed materials
B2: 46204 | C2: 380 | D2: =380 -> 380 | E2: =0 -> 0 | F2: =0 -> 0 | G2: =0 -> 0 | H2: =0 -> 0 | I2: =0 -> 0 | J2: =0 -> 0 | K2: =0 -> 0 | L2: =0 -> 0
B3: 46204 | C3: 400 | D3: =0 -> 0 | E3: =0 -> 0 | F3: =0 -> 0 | G3: =0 -> 0 | H3: =0 -> 0 | I3: =0 -> 0 | J3: =0 -> 0 | K3: =0 -> 0 | L3: =400 -> 400
B4: 46204 | C4: 240 | D4: =0 -> 0 | E4: =240 -> 240 | F4: =0 -> 0 | G4: =0 -> 0 | H4: =0 -> 0 | I4: =0 -> 0 | J4: =0 -> 0 | K4: =0 -> 0 | L4: =0 -> 0
B5: 46204 | C5: 220 | D5: =0 -> 0 | E5: =0 -> 0 | F5: =44 -> 44 | G5: =44 -> 44 | H5: =0 -> 0 | I5: =0 -> 0 | J5: =0 -> 0 | K5: =22 -> 22 | L5: =110 -> 110
B6: 46204 | C6: 240 | D6: 0 | E6: 0 | F6: 0 | G6: 0 | H6: 0 | I6: 0 | J6: 0 | K6: 0 | L6: 240
B7: 46204 | C7: 300 | D7: 0 | E7: 0 | F7: 0 | G7: 0 | H7: 0 | I7: 0 | J7: 0 | K7: 0 | L7: 300
B8: 46205 | C8: 180 | D8: =0 -> 0 | E8: =0 -> 0 | F8: =108 -> 108 | G8: =36 -> 36 | H8: =0 -> 0 | I8: =0 -> 0 | J8: =0 -> 0 | K8: =18 -> 18 | L8: =18 -> 18
B9: 46205 | C9: 180 | D9: 0 | E9: 0 | F9: 0 | G9: 0 | H9: 0 | I9: 0 | J9: 0 | K9: 0 | L9: 180
B10: 46205 | C10: 220 | D10: =0 -> 0 | E10: =0 -> 0 | F10: =0 -> 0 | G10: =0 -> 0 | H10: =0 -> 0 | I10: =0 -> 0 | J10: =44 -> 44 | K10: =0 -> 0 | L10: =176 -> 176
B11: 46205 | C11: 260 | D11: =0 -> 0 | E11: =0 -> 0 | F11: =0 -> 0 | G11: =0 -> 0 | H11: =0 -> 0 | I11: =0 -> 0 | J11: =156 -> 156 | K11: =0 -> 0 | L11: =104 -> 104
B12: 46206 | C12: 220 | D12: =220 -> 220 | E12: =0 -> 0 | F12: =0 -> 0 | G12: =0 -> 0 | H12: =0 -> 0 | I12: =0 -> 0 | J12: =0 -> 0 | K12: =0 -> 0 | L12: =0 -> 0
B13: 46206 | C13: 260 | D13: 0 | E13: 0 | F13: 0 | G13: 0 | H13: 0 | I13: 0 | J13: 0 | K13: 0 | L13: 260
B14: 46206 | C14: 260 | D14: =0 -> 0 | E14: =0 -> 0 | F14: =0 -> 0 | G14: =52 -> 52 | H14: =0 -> 0 | I14: =0 -> 0 | J14: =52 -> 52 | K14: =26 -> 26 | L14: =130 -> 130
B15: 46206 | C15: 260 | D15: =0 -> 0 | E15: =0 -> 0 | F15: =52 -> 52 | G15: =52 -> 52 | H15: =0 -> 0 | I15: =0 -> 0 | J15: =0 -> 0 | K15: =52 -> 52 | L15: =104 -> 104
B16: 46206 | C16: 40 | D16: =0 -> 0 | E16: =0 -> 0 | F16: =0 -> 0 | G16: =0 -> 0 | H16: =0 -> 0 | I16: =0 -> 0 | J16: =0 -> 0 | K16: =0 -> 0 | L16: =40 -> 40
B17: 46207 | C17: 180 | D17: =0 -> 0 | E17: =0 -> 0 | F17: =0 -> 0 | G17: =0 -> 0 | H17: =0 -> 0 | I17: =0 -> 0 | J17: =0 -> 0 | K17: =0 -> 0 | L17: =180 -> 180
B18: 46207 | C18: 20 | D18: 0 | E18: 0 | F18: 0 | G18: 0 | H18: 0 | I18: 0 | J18: 0 | K18: 0 | L18: 20
B19: 46207 | C19: 20 | D19: 0 | E19: 0 | F19: 0 | G19: 0 | H19: 0 | I19: 0 | J19: 0 | K19: 0 | L19: 20
B20: 46208 | C20: 40 | D20: =0 -> 0 | E20: =0 -> 0 | F20: =0 -> 0 | G20: =0 -> 0 | H20: =40 -> 40 | I20: =0 -> 0 | J20: =0 -> 0 | K20: =0 -> 0 | L20: =0 -> 0
B21: 46208 | C21: 20 | D21: =0 -> 0 | E21: =0 -> 0 | F21: =0 -> 0 | G21: =20 -> 20 | H21: =0 -> 0 | I21: =0 -> 0 | J21: =0 -> 0 | K21: =0 -> 0 | L21: =0 -> 0
B22: 46209 | C22: 280 | D22: =84 -> 84 | E22: =168 -> 168 | F22: =0 -> 0 | G22: =0 -> 0 | H22: =0 -> 0 | I22: =0 -> 0 | J22: =0 -> 0 | K22: =0 -> 0 | L22: =28 -> 28
B23: 46209 | C23: 220 | D23: 0 | E23: 0 | F23: 0 | G23: 0 | H23: 0 | I23: 0 | J23: 0 | K23: 0 | L23: 220
B24: 46209 | C24: 280 | D24: =0 -> 0 | E24: =280 -> 280 | F24: =0 -> 0 | G24: =0 -> 0 | H24: =0 -> 0 | I24: =0 -> 0 | J24: =0 -> 0 | K24: =0 -> 0 | L24: =0 -> 0
B25: 46209 | C25: 200 | D25: =0 -> 0 | E25: =200 -> 200 | F25: =0 -> 0 | G25: =0 -> 0 | H25: =0 -> 0 | I25: =0 -> 0 | J25: =0 -> 0 | K25: =0 -> 0 | L25: =0 -> 0
B26: 46210 | C26: 140 | D26: 0 | E26: 0 | F26: 0 | G26: 0 | H26: 0 | I26: 0 | J26: 0 | K26: 0 | L26: 140
B27: 46210 | C27: 180 | D27: 0 | E27: 0 | F27: 0 | G27: 0 | H27: 0 | I27: 0 | J27: 0 | K27: 0 | L27: 180
B28: 46210 | C28: 160 | D28: =160 -> 160 | E28: =0 -> 0 | F28: =0 -> 0 | G28: =0 -> 0 | H28: =0 -> 0 | I28: =0 -> 0 | J28: =0 -> 0 | K28: =0 -> 0 | L28: =0 -> 0
B29: 46210 | C29: 180 | D29: =0 -> 0 | E29: =0 -> 0 | F29: =36 -> 36 | G29: =126 -> 126 | H29: =0 -> 0 | I29: =0 -> 0 | J29: =0 -> 0 | K29: =18 -> 18 | L29: =0 -> 0
B30: 46210 | C30: 80 | D30: =0 -> 0 | E30: =0 -> 0 | F30: =0 -> 0 | G30: =0 -> 0 | H30: =72 -> 72 | I30: =0 -> 0 | J30: =0 -> 0 | K30: =0 -> 0 | L30: =8 -> 8
B31: 46211 | C31: 40 | D31: 0 | E31: 0 | F31: 0 | G31: 0 | H31: 0 | I31: 0 | J31: 0 | K31: 0 | L31: 40
B32: 46211 | C32: 300 | D32: 0 | E32: 0 | F32: 0 | G32: 0 | H32: 0 | I32: 0 | J32: 0 | K32: 0 | L32: 300
B33: 46211 | C33: 160 | D33: =0 -> 0 | E33: =0 -> 0 | F33: =0 -> 0 | G33: =0 -> 0 | H33: =0 -> 0 | I33: =0 -> 0 | J33: =0 -> 0 | K33: =0 -> 0 | L33: =160 -> 160
B34: 46211 | C34: 200 | D34: 0 | E34: 0 | F34: 0 | G34: 0 | H34: 0 | I34: 0 | J34: 0 | K34: 0 | L34: 200
B35: 46212 | C35: 80 | D35: 0 | E35: 0 | F35: 0 | G35: 0 | H35: 0 | I35: 0 | J35: 0 | K35: 0 | L35: 80
B36: 46212 | C36: 200 | D36: =0 -> 0 | E36: =200 -> 200 | F36: =0 -> 0 | G36: =0 -> 0 | H36: =0 -> 0 | I36: =0 -> 0 | J36: =0 -> 0 | K36: =0 -> 0 | L36: =0 -> 0
B37: 46212 | C37: 180 | D37: =180 -> 180 | E37: =0 -> 0 | F37: =0 -> 0 | G37: =0 -> 0 | H37: =0 -> 0 | I37: =0 -> 0 | J37: =0 -> 0 | K37: =0 -> 0 | L37: =0 -> 0
B38: 46212 | C38: 200 | D38: =200 -> 200 | E38: =0 -> 0 | F38: =0 -> 0 | G38: =0 -> 0 | H38: =0 -> 0 | I38: =0 -> 0 | J38: =0 -> 0 | K38: =0 -> 0 | L38: =0 -> 0
B39: 46212 | C39: 140 | D39: =0 -> 0 | E39: =0 -> 0 | F39: =42 -> 42 | G39: =28 -> 28 | H39: =0 -> 0 | I39: =0 -> 0 | J39: =0 -> 0 | K39: =28 -> 28 | L39: =42 -> 42
B40: 46213 | C40: 40 | D40: 0 | E40: 0 | F40: 0 | G40: 0 | H40: 0 | I40: 0 | J40: 0 | K40: 0 | L40: 40
...

Sheet SalvageDownList
B1: Date | C1: Weight Down | D1: Iron and steel | E1: Aluminium | F1: Other Non-Ferrous | G1: Mixed Metals | H1: Ewaste | I1: Lead Acid Batteries | J1: Timber | K1: Bricks | L1: Building and Demolition | M1: Whitegoods | N1: Paper and Cardboard | O1: Plastics | P1: Glass | Q1: Mixed Materials
B2: 46204 | C2: 100 | D2: =40 -> 40 | E2: =20 -> 20 | F2: =0 -> 0 | G2: =0 -> 0 | H2: =10 -> 10 | I2: =0 -> 0 | J2: =0 -> 0 | K2: =0 -> 0 | L2: =0 -> 0 | M2: =0 -> 0 | N2: =0 -> 0 | O2: =10 -> 10 | P2: =0 -> 0 | Q2: =20 -> 20
B3: 46204 | C3: 660 | D3: =0 -> 0 | E3: =0 -> 0 | F3: =660 -> 660 | G3: =0 -> 0 | H3: =0 -> 0 | I3: =0 -> 0 | J3: =0 -> 0 | K3: =0 -> 0 | L3: =0 -> 0 | M3: =0 -> 0 | N3: =0 -> 0 | ... Q3: =0 -> 0
B4: 46204 | C4: 60 | D4: =12 -> 12 | E4: =0 -> 0 | F4: =0 -> 0 | G4: =0 -> 0 | H4: =48 -> 48 | I4: =0 -> 0 | J4: =0 -> 0 | K4: =0 -> 0 | L4: =0 -> 0 | M4: =0 -> 0 | N4: =0 -> 0 | O4: =0 -> 0 | P4: =0 -> 0 | Q4: =0 -> 0
B5: 46204 | C5: 120 | D5: =0 -> 0 | E5: =0 -> 0 | F5: =0 -> 0 | G5: =0 -> 0 | H5: =12 -> 12 | I5: =0 -> 0 | J5: =48 -> 48 | K5: =60 -> 60 | L5: =0 -> 0 | M5: =0 -> 0 | N5: =0 -> 0 | O5: =0 -> 0 | P5: =0 -> 0 | Q5: =0 -> 0
B6: 46204 | C6: 100 | D6: =0 -> 0 | E6: =0 -> 0 | F6: =0 -> 0 | G6: =0 -> 0 | H6: =0 -> 0 | I6: =100 -> 100 | J6: =0 -> 0 | K6: =0 -> 0 | L6: =0 -> 0 | M6: =0 -> 0 | N6: =0 -> 0 | O6: =0 -> 0 | P6: =0 -> 0 | Q6: =0 -> 0
B7: 46204 | C7: 80 | D7: =0 -> 0 | E7: =0 -> 0 | F7: =0 -> 0 | G7: =0 -> 0 | H7: =0 -> 0 | I7: =0 -> 0 | J7: =80 -> 80 | K7: =0 -> 0 | L7: =0 -> 0 | M7: =0 -> 0 | N7: =0 -> 0 | O7: =0 -> 0 | P7: =0 -> 0 | Q7: =0 -> 0
B8: 46205 | C8: 180 | D8: =0 -> 0 | E8: =0 -> 0 | F8: =36 -> 36 | G8: =0 -> 0 | H8: =36 -> 36 | I8: =0 -> 0 | J8: =0 -> 0 | K8: =0 -> 0 | L8: =0 -> 0 | M8: =0 -> 0 | N8: =0 -> 0 | O8: =36 -> 36 | P8: =0 -> 0 | Q8: =72 -> 72
B9: 46205 | C9: 80 | D9: =0 -> 0 | E9: =0 -> 0 | F9: =0 -> 0 | G9: =0 -> 0 | H9: =0 -> 0 | I9: =64 -> 64 | J9: =0 -> 0 | K9: =0 -> 0 | L9: =0 -> 0 | M9: =0 -> 0 | N9: =0 -> 0 | O9: =0 -> 0 | P9: =0 -> 0 | Q9: =16 -> 16
B10: 46205 | C10: 100 | D10: =0 -> 0 | E10: =0 -> 0 | F10: =0 -> 0 | G10: =0 -> 0 | H10: =100 -> 100 | I10: =0 -> 0 | J10: =0 -> 0 | K10: =0 -> 0 | L10: =0 -> 0 | M10: =0 -> 0 | N10: =0 -> 0 | O10: =0 -> 0 | P10: =0 -> 0 | Q10: =0 -> 0
B11: 46205 | C11: 580 | D11: =0 -> 0 | E11: =0 -> 0 | F11: =0 -> 0 | G11: =0 -> 0 | H11: =0 -> 0 | I11: =0 -> 0 | J11: =580 -> 580 | K11: =0 -> 0 | L11: =0 -> 0 | M11: =0 -> 0 | N11: =0 -> 0 | O11: =0 -> 0 | P11: =0 -> 0 | Q11: =0 -> 0
B12: 46206 | C12: 20 | D12: =20 -> 20 | E12: =0 -> 0 | F12: =0 -> 0 | G12: =0 -> 0 | H12: =0 -> 0 | I12: =0 -> 0 | J12: =0 -> 0 | K12: =0 -> 0 | L12: =0 -> 0 | ... Q12: =0 -> 0
B13: 46206 | C13: 20 | D13: 0 | E13: 0 | F13: 0 | G13: 0 | H13: 0 | I13: 0 | J13: 0 | K13: 0 | L13: 0 | M13: 0 | N13: 0 | O13: 0 | P13: 0 | Q13: 20
B14: 46206 | C14: 100 | D14: =0 -> 0 | E14: =0 -> 0 | F14: =0 -> 0 | G14: =0 -> 0 | H14: =0 -> 0 | I14: =0 -> 0 | J14: =10 -> 10 | K14: =90 -> 90 | L14: =0 -> 0 | M14: =0 -> 0 | N14: =0 -> 0 | O14: =0 -> 0 | P14: =0 -> 0 | Q14: =0 -> 0
B15: 46206 | C15: 100 | D15: =10 -> 10 | E15: =0 -> 0 | F15: =0 -> 0 | G15: =0 -> 0 | H15: =0 -> 0 | I15: =0 -> 0 | J15: =90 -> 90 | K15: =0 -> 0 | L15: =0 -> 0 | M15: =0 -> 0 | N15: =0 -> 0 | O15: =0 -> 0 | P15: =0 -> 0 | Q15: =0 -> 0
B16: 46206 | C16: 160 | D16: =64 -> 64 | E16: =0 -> 0 | F16: =0 -> 0 | G16: =0 -> 0 | H16: =0 -> 0 | I16: =96 -> 96 | J16: =0 -> 0 | K16: =0 -> 0 | L16: =0 -> 0 | M16: =0 -> 0 | N16: =0 -> 0 | O16: =0 -> 0 | P16: =0 -> 0 | Q16: =0 -> 0
B17: 46206 | C17: 280 | D17: =84 -> 84 | E17: =0 -> 0 | F17: =0 -> 0 | G17: =0 -> 0 | H17: =0 -> 0 | I17: =0 -> 0 | J17: =0 -> 0 | K17: =168 -> 168 | L17: =28 -> 28 | M17: =0 -> 0 | N17: =0 -> 0 | O17: =0 -> 0 | P17: =0 -> 0 | Q17: =0 -> 0
B18: 46207 | C18: 20 | D18: =6 -> 6 | E18: =0 -> 0 | F18: =0 -> 0 | G18: =0 -> 0 | H18: =0 -> 0 | I18: =0 -> 0 | J18: =6 -> 6 | K18: =0 -> 0 | L18: =0 -> 0 | M18: =0 -> 0 | N18: =0 -> 0 | O18: =6 -> 6 | P18: =0 -> 0 | Q18: =2 -> 2
B19: 46207 | C19: 100 | D19: =50 -> 50 | E19: =0 -> 0 | F19: =0 -> 0 | G19: =0 -> 0 | H19: =0 -> 0 | I19: =10 -> 10 | J19: =0 -> 0 | K19: =0 -> 0 | L19: =0 -> 0 | M19: =0 -> 0 | N19: =0 -> 0 | O19: =0 -> 0 | P19: =0 -> 0 | Q19: =40 -> 40
B20: 46208 | C20: 120 | D20: =24 -> 24 | E20: =0 -> 0 | F20: =0 -> 0 | G20: =0 -> 0 | H20: =84 -> 84 | I20: =0 -> 0 | J20: =0 -> 0 | K20: =0 -> 0 | L20: =0 -> 0 | M20: =0 -> 0 | N20: =0 -> 0 | O20: =0 -> 0 | P20: =0 -> 0 | Q20: =12 -> 12
B21: 46209 | C21: 100 | D21: =30 -> 30 | E21: =0 -> 0 | F21: =0 -> 0 | G21: =0 -> 0 | H21: =10 -> 10 | I21: =0 -> 0 | J21: =50 -> 50 | K21: =0 -> 0 | L21: =0 -> 0 | M21: =0 -> 0 | N21: =0 -> 0 | O21: =10 -> 10 | P21: =0 -> 0 | Q21: =0 -> 0
B22: 46209 | C22: 60 | D22: 0 | E22: 0 | F22: 0 | G22: 0 | H22: 0 | I22: 0 | J22: 0 | K22: 0 | L22: 0 | M22: 0 | N22: 0 | O22: 0 | P22: 0 | Q22: 60
B23: 46209 | C23: 80 | D23: 0 | E23: 0 | F23: 0 | G23: 0 | H23: 0 | I23: 0 | J23: 0 | K23: 0 | L23: 0 | M23: 0 | N23: 0 | O23: 0 | P23: 0 | Q23: 80
B24: 46209 | C24: 120 | D24: =60 -> 60 | E24: =0 -> 0 | F24: =0 -> 0 | G24: =0 -> 0 | H24: =0 -> 0 | I24: =0 -> 0 | J24: =60 -> 60 | K24: =0 -> 0 | L24: =0 -> 0 | M24: =0 -> 0 | N24: =0 -> 0 | O24: =0 -> 0 | P24: =0 -> 0 | Q24: =0 -> 0
B25: 46209 | C25: 60 | D25: 0 | E25: 0 | F25: 0 | G25: 0 | H25: 0 | I25: 0 | J25: 0 | K25: 0 | L25: 0 | M25: 0 | N25: 0 | O25: 0 | P25: 0 | Q25: 60
B26: 46210 | C26: 100 | D26: =0 -> 0 | E26: =0 -> 0 | F26: =0 -> 0 | G26: =90 -> 90 | H26: =0 -> 0 | I26: =10 -> 10 | J26: =0 -> 0 | K26: =0 -> 0 | L26: =0 -> 0 | M26: =0 -> 0 | N26: =0 -> 0 | O26: =0 -> 0 | P26: =0 -> 0 | Q26: =0 -> 0
B27: 46210 | C27: 40 | D27: 0 | E27: 0 | F27: 0 | G27: 0 | H27: 0 | I27: 0 | J27: 0 | K27: 0 | L27: 0 | M27: 0 | N27: 0 | O27: 0 | P27: 0 | Q27: 40
B28: 46210 | C28: 40 | D28: 0 | E28: 0 | F28: 0 | G28: 0 | H28: 0 | I28: 0 | J28: 0 | K28: 0 | L28: 0 | M28: 0 | N28: 0 | O28: 0 | P28: 0 | Q28: 40
B29: 46210 | C29: 120 | D29: =0 -> 0 | E29: =0 -> 0 | F29: =24 -> 24 | G29: =0 -> 0 | H29: =0 -> 0 | I29: =0 -> 0 | J29: =12 -> 12 | K29: =84 -> 84 | L29: =0 -> 0 | M29: =0 -> 0 | N29: =0 -> 0 | O29: =0 -> 0 | P29: =0 -> 0 | Q29: =0 -> 0
B30: 46210 | C30: 100 | D30: =0 -> 0 | E30: =0 -> 0 | F30: =0 -> 0 | G30: =0 -> 0 | H30: =50 -> 50 | I30: =0 -> 0 | J30: =0 -> 0 | K30: =0 -> 0 | L30: =50 -> 50 | M30: =0 -> 0 | N30: =0 -> 0 | O30: =0 -> 0 | P30: =0 -> 0 | Q30: =0 -> 0
B31: 46211 | C31: 380 | D31: =76 -> 76 | E31: =304 -> 304 | F31: =0 -> 0 | G31: =0 -> 0 | H31: =0 -> 0 | I31: =0 -> 0 | J31: =0 -> 0 | K31: =0 -> 0 | L31: =0 -> 0 | M31: =0 -> 0 | ... Q31: =0 -> 0
B32: 46211 | C32: 160 | D32: =0 -> 0 | E32: =0 -> 0 | F32: =0 -> 0 | G32: =0 -> 0 | H32: =0 -> 0 | I32: =0 -> 0 | J32: =160 -> 160 | K32: =0 -> 0 | L32: =0 -> 0 | M32: =0 -> 0 | N32: =0 -> 0 | O32: =0 -> 0 | P32: =0 -> 0 | Q32: =0 -> 0
B33: 46211 | C33: 160 | D33: =0 -> 0 | E33: =0 -> 0 | F33: =0 -> 0 | G33: =0 -> 0 | H33: =0 -> 0 | I33: =0 -> 0 | J33: =160 -> 160 | K33: =0 -> 0 | L33: =0 -> 0 | M33: =0 -> 0 | N33: =0 -> 0 | O33: =0 -> 0 | P33: =0 -> 0 | Q33: =0 -> 0
B34: 46211 | C34: 240 | D34: =216 -> 216 | E34: =24 -> 24 | F34: =0 -> 0 | G34: =0 -> 0 | H34: =0 -> 0 | I34: =0 -> 0 | J34: =0 -> 0 | K34: =0 -> 0 | L34: =0 -> 0 | M34: =0 -> 0 | ... Q34: =0 -> 0
B35: 46212 | C35: 120 | D35: =0 -> 0 | E35: =0 -> 0 | F35: =0 -> 0 | G35: =0 -> 0 | H35: =0 -> 0 | I35: =24 -> 24 | J35: =0 -> 0 | K35: =0 -> 0 | L35: =0 -> 0 | M35: =0 -> 0 | N35: =0 -> 0 | O35: =0 -> 0 | P35: =0 -> 0 | Q35: =96 -> 96
B36: 46212 | C36: 100 | D36: =30 -> 30 | E36: =0 -> 0 | F36: =0 -> 0 | G36: =0 -> 0 | H36: =0 -> 0 | I36: =0 -> 0 | J36: =0 -> 0 | K36: =0 -> 0 | L36: =0 -> 0 | ... P36: =0 -> 0 | Q36: =70 -> 70
B37: 46212 | C37: 200 | D37: =200 -> 200 | E37: =0 -> 0 | F37: =0 -> 0 | G37: =0 -> 0 | H37: =0 -> 0 | I37: =0 -> 0 | J37: =0 -> 0 | K37: =0 -> 0 | L37: =0 -> 0 | ... Q37: =0 -> 0
B38: 46212 | C38: 100 | D38: 0 | E38: 0 | F38: 0 | G38: 0 | H38: 0 | I38: 0 | J38: 0 | K38: 0 | L38: 0 | M38: 0 | N38: 0 | O38: 0 | P38: 0 | Q38: 100
B39: 46212 | C39: 40 | D39: =0 -> 0 | E39: =0 -> 0 | F39: =0 -> 0 | G39: =0 -> 0 | H39: =40 -> 40 | I39: =0 -> 0 | J39: =0 -> 0 | K39: =0 -> 0 | L39: =0 -> 0 | M39: =0 -> 0 | N39: =0 -> 0 | O39: =0 -> 0 | P39: =0 -> 0 | Q39: =0 -> 0
B40: 46213 | C40: 460 | D40: =0 -> 0 | E40: =46 -> 46 | F40: =0 -> 0 | G40: =138 -> 138 | H40: =0 -> 0 | I40: =0 -> 0 | J40: =276 -> 276 | K40: =0 -> 0 | L40: =0 -> 0 | M40: =0 -> 0 | N40: =0 -> 0 | O40: =0 -> 0 | P40: =0 -> 0 | Q40: =0 -> 0
...

Sheet CrateList
B1: Date | C1: Iron and steel | D1: Aluminium | E1: Other non-ferrous | F1: Mixed metals | G1: Textiles | H1: Mattresses | I1: Timber | J1: Bricks | K1: Demolition | L1: Paper and cardboard | M1: Plastics | N1: Glass | O1: Mixed materials
B2: 46204 | C2: =0 -> 0 | D2: =0 -> 0 | E2: =0 -> 0 | F2: =11.2 -> 11.2 | G2: =44.8 -> 44.8 | H2: =0 -> 0 | I2: =0 -> 0 | J2: =0 -> 0 | K2: =0 -> 0 | L2: =22.4 -> 22.4 | M2: =11.2 -> 11.2 | N2: =0 -> 0 | O2: =22.4 -> 22.4
B3: 46204 | C3: =0 -> 0 | D3: =0 -> 0 | E3: =0 -> 0 | F3: =31 -> 31 | G3: =46.5 -> 46.5 | H3: =0 -> 0 | I3: =0 -> 0 | J3: =0 -> 0 | K3: =0 -> 0 | L3: =46.5 -> 46.5 | M3: =31 -> 31 | N3: =0 -> 0 | O3: =0 -> 0
B4: 46204 | C4: =0 -> 0 | D4: =0 -> 0 | E4: =0 -> 0 | F4: =0 -> 0 | G4: =17.7 -> 17.7 | H4: =0 -> 0 | I4: =0 -> 0 | J4: =0 -> 0 | K4: =0 -> 0 | L4: =17.7 -> 17.7 | M4: =5.9 -> 5.9 | N4: =0 -> 0 | O4: =17.7 -> 17.7
B5: 46204 | C5: 0 | D5: 0 | E5: 0 | F5: 0 | G5: 0 | H5: 0 | I5: 0 | J5: 0 | K5: 0 | L5: 0 | M5: 0 | N5: 0 | O5: =142 -> 142
B6: 46204 | C6: =0 -> 0 | D6: =0 -> 0 | E6: =0 -> 0 | F6: =0 -> 0 | G6: =42.6 -> 42.6 | H6: =0 -> 0 | I6: =0 -> 0 | J6: =0 -> 0 | K6: =0 -> 0 | L6: =0 -> 0 | M6: =21.3 -> 21.3 | N6: =14.2 -> 14.2 | O6: =63.9 -> 63.9
B7: 46205 | C7: =0 -> 0 | D7: =0 -> 0 | E7: =0 -> 0 | F7: =0 -> 0 | G7: =95.2 -> 95.2 | H7: =0 -> 0 | I7: =0 -> 0 | J7: =0 -> 0 | K7: =0 -> 0 | L7: =0 -> 0 | M7: =0 -> 0 | N7: =0 -> 0 | O7: =23.8 -> 23.8
B8: 46205 | C8: 0 | D8: 0 | E8: 0 | F8: 0 | G8: 0 | H8: 0 | I8: 0 | J8: 0 | K8: 0 | L8: 0 | M8: 0 | N8: 0 | O8: =33.4 -> 33.4
B9: 46205 | C9: =0 -> 0 | D9: =0 -> 0 | E9: =0 -> 0 | F9: =0 -> 0 | G9: =0 -> 0 | H9: =0 -> 0 | I9: =0 -> 0 | J9: =0 -> 0 | ... L9: =0 -> 0 | M9: =107.2 -> 107.2 | N9: =0 -> 0 | O9: =26.8 -> 26.8
B10: 46206 | C10: =0 -> 0 | D10: =0 -> 0 | E10: =0 -> 0 | F10: =0 -> 0 | G10: =0 -> 0 | H10: =0 -> 0 | I10: =0 -> 0 | J10: =0 -> 0 | ... L10: =0 -> 0 | M10: =157 -> 157 | N10: =0 -> 0 | O10: =0 -> 0
B11: 46206 | C11: =14.4 -> 14.4 | D11: =0 -> 0 | E11: =0 -> 0 | F11: =0 -> 0 | G11: =43.2 -> 43.2 | H11: =0 -> 0 | I11: =0 -> 0 | J11: =0 -> 0 | K11: =0 -> 0 | L11: =43.2 -> 43.2 | M11: =28.8 -> 28.8 | N11: =14.4 -> 14.4 | O11: =0 -> 0
B12: 46206 | C12: =0 -> 0 | D12: =0 -> 0 | E12: =0 -> 0 | F12: =0 -> 0 | G12: =118.4 -> 118.4 | H12: =0 -> 0 | I12: =0 -> 0 | J12: =0 -> 0 | K12: =0 -> 0 | L12: =29.6 -> 29.6 | M12: =0 -> 0 | N12: =0 -> 0 | O12: =0 -> 0
B13: 46207 | C13: 0 | D13: 0 | E13: 0 | F13: 0 | G13: 0 | H13: 0 | I13: 0 | J13: 0 | K13: 0 | L13: 0 | M13: 0 | N13: 0 | O13: =131 -> 131
B14: 46207 | C14: 0 | D14: 0 | E14: 0 | F14: 0 | G14: 0 | H14: 0 | I14: 0 | J14: 0 | K14: 0 | L14: 0 | M14: 0 | N14: 0 | O14: =136 -> 136
B15: 46207 | C15: =120.9 -> 120.9 | D15: =0 -> 0 | E15: =0 -> 0 | F15: =0 -> 0 | G15: =161.2 -> 161.2 | H15: =0 -> 0 | I15: =0 -> 0 | J15: =0 -> 0 | K15: =0 -> 0 | L15: =0 -> 0 | M15: =0 -> 0 | N15: =0 -> 0 | O15: =120.9 -> 120.9
B16: 46208 | C16: =0 -> 0 | D16: =0 -> 0 | E16: =0 -> 0 | F16: =0 -> 0 | G16: =49 -> 49 | H16: =0 -> 0 | I16: =0 -> 0 | J16: =0 -> 0 | K16: =0 -> 0 | L16: =0 -> 0 | M16: =35 -> 35 | N16: =35 -> 35 | O16: =21 -> 21
B17: 46208 | C17: 0 | D17: 0 | E17: 0 | F17: 0 | G17: 0 | H17: 0 | I17: 0 | J17: 0 | K17: 0 | L17: 0 | M17: 0 | N17: 0 | O17: =150 -> 150
B18: 46209 | C18: =26.4 -> 26.4 | D18: =0 -> 0 | E18: =0 -> 0 | F18: =0 -> 0 | G18: =52.8 -> 52.8 | H18: =0 -> 0 | I18: =0 -> 0 | J18: =0 -> 0 | K18: =0 -> 0 | L18: =0 -> 0 | M18: =0 -> 0 | N18: =0 -> 0 | O18: =52.8 -> 52.8
B19: 46209 | C19: =0 -> 0 | D19: =0 -> 0 | E19: =0 -> 0 | F19: =0 -> 0 | G19: =52.5 -> 52.5 | H19: =0 -> 0 | I19: =0 -> 0 | J19: =0 -> 0 | K19: =0 -> 0 | L19: =0 -> 0 | M19: =0 -> 0 | N19: =0 -> 0 | O19: =52.5 -> 52.5
B20: 46209 | C20: =0 -> 0 | D20: =0 -> 0 | E20: =0 -> 0 | F20: =0 -> 0 | G20: =38.4 -> 38.4 | H20: =0 -> 0 | I20: =0 -> 0 | J20: =0 -> 0 | K20: =0 -> 0 | L20: =0 -> 0 | M20: =0 -> 0 | N20: =4.8 -> 4.8 | O20: =52.8 -> 52.8
B21: 46209 | C21: =0 -> 0 | D21: =0 -> 0 | E21: =0 -> 0 | F21: =0 -> 0 | G21: =51 -> 51 | H21: =0 -> 0 | I21: =0 -> 0 | J21: =0 -> 0 | K21: =0 -> 0 | L21: =51 -> 51 | M21: =51 -> 51 | N21: =0 -> 0 | O21: =17 -> 17
B22: 46210 | C22: =0 -> 0 | D22: =0 -> 0 | E22: =0 -> 0 | F22: =0 -> 0 | G22: =47.4 -> 47.4 | H22: =0 -> 0 | I22: =0 -> 0 | J22: =0 -> 0 | K22: =0 -> 0 | L22: =94.8 -> 94.8 | M22: =0 -> 0 | N22: =0 -> 0 | O22: =15.8 -> 15.8
B23: 46210 | C23: =23.6 -> 23.6 | D23: =23.6 -> 23.6 | E23: =0 -> 0 | F23: =0 -> 0 | G23: =0 -> 0 | H23: =0 -> 0 | I23: =0 -> 0 | J23: =0 -> 0 | K23: =0 -> 0 | L23: =0 -> 0 | M23: =47.2 -> 47.2 | N23: =23.6 -> 23.6 | O23: =0 -> 0
B24: 46210 | C24: =0 -> 0 | D24: =0 -> 0 | E24: =0 -> 0 | F24: =0 -> 0 | G24: =53.6 -> 53.6 | H24: =0 -> 0 | I24: =0 -> 0 | J24: =0 -> 0 | K24: =0 -> 0 | L24: =40.2 -> 40.2 | M24: =0 -> 0 | N24: =0 -> 0 | O24: =40.2 -> 40.2
B25: 46211 | C25: =0 -> 0 | D25: =0 -> 0 | E25: =0 -> 0 | F25: =0 -> 0 | G25: =136.2 -> 136.2 | H25: =0 -> 0 | I25: =0 -> 0 | J25: =0 -> 0 | K25: =0 -> 0 | L25: =90.8 -> 90.8 | M25: =0 -> 0 | N25: =0 -> 0 | O25: =0 -> 0
B26: 46211 | C26: =0 -> 0 | D26: =0 -> 0 | E26: =0 -> 0 | F26: =0 -> 0 | G26: =141.6 -> 141.6 | H26: =0 -> 0 | I26: =0 -> 0 | J26: =0 -> 0 | K26: =0 -> 0 | L26: =0 -> 0 | M26: =0 -> 0 | N26: =0 -> 0 | O26: =35.4 -> 35.4
B27: 46211 | C27: =0 -> 0 | D27: =0 -> 0 | E27: =0 -> 0 | F27: =0 -> 0 | G27: =0 -> 0 | H27: =0 -> 0 | I27: =0 -> 0 | J27: =0 -> 0 | K27: =0 -> 0 | L27: =63.2 -> 63.2 | M27: =0 -> 0 | N27: =0 -> 0 | O27: =94.8 -> 94.8
B28: 46212 | C28: =28.8 -> 28.8 | D28: =0 -> 0 | E28: =0 -> 0 | F28: =0 -> 0 | G28: =28.8 -> 28.8 | H28: =0 -> 0 | I28: =0 -> 0 | J28: =0 -> 0 | K28: =0 -> 0 | L28: =0 -> 0 | M28: =28.8 -> 28.8 | N28: =0 -> 0 | O28: =9.6 -> 9.6
B29: 46213 | C29: =0 -> 0 | D29: =0 -> 0 | E29: =0 -> 0 | F29: =0 -> 0 | G29: =84 -> 84 | H29: =0 -> 0 | I29: =0 -> 0 | J29: =0 -> 0 | K29: =0 -> 0 | L29: =12 -> 12 | M29: =12 -> 12 | N29: =0 -> 0 | O29: =12 -> 12
B30: 46213 | C30: =0 -> 0 | D30: =0 -> 0 | E30: =0 -> 0 | F30: =0 -> 0 | G30: =97.6 -> 97.6 | H30: =0 -> 0 | I30: =0 -> 0 | J30: =0 -> 0 | K30: =0 -> 0 | L30: =12.2 -> 12.2 | M30: =0 -> 0 | N30: =0 -> 0 | O30: =12.2 -> 12.2
B31: 46213 | C31: =0 -> 0 | D31: =0 -> 0 | E31: =0 -> 0 | F31: =0 -> 0 | G31: =109.9 -> 109.9 | H31: =0 -> 0 | I31: =15.7 -> 15.7 | J31: =0 -> 0 | K31: =0 -> 0 | L31: =0 -> 0 | M31: =31.4 -> 31.4 | N31: =0 -> 0 | O31: =0 -> 0
B32: 46213 | C32: 0 | D32: 0 | E32: 0 | F32: 0 | G32: 0 | H32: 0 | I32: 0 | J32: 0 | K32: 0 | L32: 0 | M32: 0 | N32: 0 | O32: =107 -> 107
B33: 46214 | C33: =0 -> 0 | D33: =0 -> 0 | E33: =0 -> 0 | F33: =0 -> 0 | G33: =36.6 -> 36.6 | H33: =0 -> 0 | I33: =0 -> 0 | J33: =0 -> 0 | K33: =0 -> 0 | L33: =128.1 -> 128.1 | M33: =0 -> 0 | N33: =0 -> 0 | O33: =18.3 -> 18.3
B34: 46214 | C34: =14.6 -> 14.6 | D34: =0 -> 0 | E34: =0 -> 0 | F34: =0 -> 0 | G34: =43.8 -> 43.8 | H34: =0 -> 0 | I34: =0 -> 0 | J34: =0 -> 0 | K34: =0 -> 0 | L34: =0 -> 0 | M34: =58.4 -> 58.4 | N34: =0 -> 0 | O34: =29.2 -> 29.2
B35: 46214 | C35: =0 -> 0 | D35: =0 -> 0 | E35: =0 -> 0 | F35: =0 -> 0 | G35: =41.1 -> 41.1 | H35: =0 -> 0 | I35: =0 -> 0 | J35: =0 -> 0 | K35: =0 -> 0 | L35: =41.1 -> 41.1 | M35: =0 -> 0 | N35: =0 -> 0 | O35: =54.8 -> 54.8
B36: 46215 | C36: =0 -> 0 | D36: =0 -> 0 | E36: =0 -> 0 | F36: =0 -> 0 | G36: =46.8 -> 46.8 | H36: =0 -> 0 | I36: =0 -> 0 | J36: =0 -> 0 | K36: =0 -> 0 | L36: =0 -> 0 | M36: =0 -> 0 | N36: =0 -> 0 | O36: =31.2 -> 31.2
B37: 46215 | C37: =0 -> 0 | D37: =0 -> 0 | E37: =0 -> 0 | F37: =0 -> 0 | G37: =57.9 -> 57.9 | H37: =0 -> 0 | I37: =0 -> 0 | J37: =0 -> 0 | K37: =0 -> 0 | L37: =57.9 -> 57.9 | M37: =0 -> 0 | N37: =0 -> 0 | O37: =77.2 -> 77.2
B38: 46215 | C38: 0 | D38: 0 | E38: 0 | F38: 0 | G38: 0 | H38: 0 | I38: 0 | J38: 0 | K38: 0 | L38: 0 | M38: 0 | N38: 0 | O38: =147 -> 147
B39: 46216 | C39: =0 -> 0 | D39: =0 -> 0 | E39: =0 -> 0 | F39: =0 -> 0 | G39: =80 -> 80 | H39: =0 -> 0 | I39: =0 -> 0 | J39: =0 -> 0 | K39: =0 -> 0 | L39: =80 -> 80 | M39: =20 -> 20 | N39: =20 -> 20 | O39: =0 -> 0
B40: 46216 | C40: =0 -> 0 | D40: =0 -> 0 | E40: =0 -> 0 | F40: =0 -> 0 | G40: =39.3 -> 39.3 | H40: =0 -> 0 | I40: =0 -> 0 | J40: =0 -> 0 | K40: =0 -> 0 | L40: =39.3 -> 39.3 | M40: =26.2 -> 26.2 | N40: =0 -> 0 | O40: =26.2 -> 26.2
...

Sheet PalletList
B1: Date | C1: Iron and steel | D1: Aluminium | E1: Other non-ferrous | F1: Mixed metals | G1: Textiles | H1: Mattresses | I1: Timber | J1: Bricks | K1: Demolition | L1: Paper and cardboard | M1: Plastics | N1: Glass | O1: Mixed materials
B2: 46204 | C2: =14.4 -> 14.4 | D2: =0 -> 0 | E2: =0 -> 0 | F2: =0 -> 0 | G2: =0 -> 0 | H2: =0 -> 0 | I2: =7.2 -> 7.2 | J2: =0 -> 0 | K2: =0 -> 0 | L2: =0 -> 0 | M2: =2.4 -> 2.4 | N2: =0 -> 0 | O2: =0 -> 0
B3: 46204 | C3: =25.2 -> 25.2 | D3: =0 -> 0 | E3: =0 -> 0 | F3: =0 -> 0 | G3: =0 -> 0 | H3: =0 -> 0 | I3: =31.5 -> 31.5 | J3: =0 -> 0 | K3: =0 -> 0 | L3: =0 -> 0 | M3: =6.3 -> 6.3 | N3: =0 -> 0 | O3: =0 -> 0
B4: 46204 | C4: =51.2 -> 51.2 | D4: =0 -> 0 | E4: =0 -> 0 | F4: =0 -> 0 | G4: =0 -> 0 | H4: =0 -> 0 | I4: =6.4 -> 6.4 | J4: =0 -> 0 | K4: =0 -> 0 | L4: =0 -> 0 | M4: =0 -> 0 | N4: =0 -> 0 | O4: =6.4 -> 6.4
B5: 46204 | C5: =43.2 -> 43.2 | D5: =0 -> 0 | E5: =0 -> 0 | F5: =0 -> 0 | G5: =0 -> 0 | H5: =0 -> 0 | I5: =0 -> 0 | J5: =0 -> 0 | K5: =0 -> 0 | L5: =0 -> 0 | M5: =4.8 -> 4.8 | N5: =0 -> 0 | O5: =0 -> 0
B6: 46204 | C6: =0 -> 0 | D6: =0 -> 0 | E6: =0 -> 0 | F6: =0 -> 0 | G6: =41 -> 41 | H6: =0 -> 0 | I6: =0 -> 0 | J6: =0 -> 0 | K6: =0 -> 0 | L6: =0 -> 0 | M6: =0 -> 0 | N6: =0 -> 0 | O6: =0 -> 0
B7: 46204 | C7: =105 -> 105 | D7: =0 -> 0 | E7: =0 -> 0 | F7: =0 -> 0 | G7: =0 -> 0 | H7: =0 -> 0 | I7: =0 -> 0 | J7: =0 -> 0 | K7: =0 -> 0 | ... O7: =0 -> 0
B8: 46204 | C8: 0 | D8: 0 | E8: 0 | F8: 0 | G8: 0 | H8: 0 | I8: 0 | J8: 0 | K8: 0 | L8: 0 | M8: 0 | N8: 0 | O8: =34 -> 34
B9: 46204 | C9: =0 -> 0 | D9: =0 -> 0 | E9: =0 -> 0 | F9: =0 -> 0 | G9: =0 -> 0 | H9: =0 -> 0 | I9: =0 -> 0 | J9: =126 -> 126 | K9: =0 -> 0 | L9: =0 -> 0 | M9: =0 -> 0 | N9: =0 -> 0 | O9: =0 -> 0
B10: 46204 | C10: =0 -> 0 | D10: =0 -> 0 | E10: =0 -> 0 | F10: =44 -> 44 | G10: =0 -> 0 | H10: =0 -> 0 | I10: =0 -> 0 | J10: =0 -> 0 | K10: =0 -> 0 | L10: =0 -> 0 | M10: =0 -> 0 | N10: =0 -> 0 | O10: =0 -> 0
B11: 46204 | C11: =0 -> 0 | D11: =0 -> 0 | E11: =0 -> 0 | F11: =0 -> 0 | G11: =0 -> 0 | H11: =0 -> 0 | I11: =9 -> 9 | J11: =0 -> 0 | K11: =0 -> 0 | L11: =0 -> 0 | M11: =6 -> 6 | N11: =0 -> 0 | O11: =0 -> 0
B12: 46205 | C12: =27 -> 27 | D12: =0 -> 0 | E12: =0 -> 0 | F12: =0 -> 0 | G12: =0 -> 0 | H12: =0 -> 0 | I12: =27 -> 27 | J12: =0 -> 0 | K12: =0 -> 0 | L12: =0 -> 0 | M12: =0 -> 0 | N12: =0 -> 0 | O12: =0 -> 0
B13: 46205 | C13: =2.6 -> 2.6 | D13: =0 -> 0 | E13: =0 -> 0 | F13: =0 -> 0 | G13: =0 -> 0 | H13: =0 -> 0 | I13: =20.8 -> 20.8 | J13: =0 -> 0 | K13: =0 -> 0 | L13: =0 -> 0 | M13: =0 -> 0 | N13: =2.6 -> 2.6 | O13: =0 -> 0
B14: 46205 | C14: =3.8 -> 3.8 | D14: =0 -> 0 | E14: =0 -> 0 | F14: =0 -> 0 | G14: =0 -> 0 | H14: =0 -> 0 | I14: =3.8 -> 3.8 | J14: =0 -> 0 | K14: =0 -> 0 | L14: =0 -> 0 | M14: =0 -> 0 | N14: =0 -> 0 | O14: =11.4 -> 11.4
B15: 46205 | C15: =48 -> 48 | D15: =0 -> 0 | E15: =0 -> 0 | F15: =0 -> 0 | G15: =0 -> 0 | H15: =0 -> 0 | I15: =0 -> 0 | J15: =0 -> 0 | K15: =0 -> 0 | ... O15: =0 -> 0
B16: 46205 | C16: =0 -> 0 | D16: =0 -> 0 | E16: =0 -> 0 | F16: =0 -> 0 | G16: =66 -> 66 | H16: =0 -> 0 | I16: =66 -> 66 | J16: =0 -> 0 | K16: =0 -> 0 | L16: =0 -> 0 | M16: =0 -> 0 | N16: =0 -> 0 | O16: =0 -> 0
B17: 46205 | C17: =0 -> 0 | D17: =0 -> 0 | E17: =0 -> 0 | F17: =66 -> 66 | G17: =0 -> 0 | H17: =0 -> 0 | I17: =0 -> 0 | J17: =0 -> 0 | K17: =0 -> 0 | L17: =0 -> 0 | M17: =0 -> 0 | N17: =0 -> 0 | O17: =0 -> 0
B18: 46206 | C18: 0 | D18: 0 | E18: 0 | F18: 0 | G18: 0 | H18: 0 | I18: 0 | J18: 0 | K18: 0 | L18: 0 | M18: 0 | N18: 0 | O18: =59 -> 59
B19: 46206 | C19: 0 | D19: 0 | E19: 0 | F19: 0 | G19: 0 | H19: 0 | I19: 0 | J19: 0 | K19: 0 | L19: 0 | M19: 0 | N19: 0 | O19: =66 -> 66
B20: 46206 | C20: =0 -> 0 | D20: =10 -> 10 | E20: =0 -> 0 | F20: =0 -> 0 | G20: =0 -> 0 | H20: =0 -> 0 | I20: =40 -> 40 | J20: =0 -> 0 | K20: =0 -> 0 | L20: =0 -> 0 | M20: =0 -> 0 | N20: =0 -> 0 | O20: =0 -> 0
B21: 46206 | C21: 0 | D21: 0 | E21: 0 | F21: 0 | G21: 0 | H21: 0 | I21: 0 | J21: 0 | K21: 0 | L21: 0 | M21: 0 | N21: 0 | O21: =72 -> 72
B22: 46206 | C22: =4.8 -> 4.8 | D22: =0 -> 0 | E22: =0 -> 0 | F22: =0 -> 0 | G22: =0 -> 0 | H22: =0 -> 0 | I22: =14.4 -> 14.4 | J22: =0 -> 0 | K22: =0 -> 0 | L22: =0 -> 0 | M22: =4.8 -> 4.8 | N22: =0 -> 0 | O22: =0 -> 0
B23: 46206 | C23: =0 -> 0 | D23: =0 -> 0 | E23: =0 -> 0 | F23: =0 -> 0 | G23: =6 -> 6 | H23: =0 -> 0 | I23: =0 -> 0 | J23: =0 -> 0 | K23: =0 -> 0 | L23: =0 -> 0 | M23: =24 -> 24 | N23: =0 -> 0 | O23: =0 -> 0
B24: 46206 | C24: =11.6 -> 11.6 | D24: =0 -> 0 | E24: =0 -> 0 | F24: =0 -> 0 | G24: =0 -> 0 | H24: =0 -> 0 | I24: =0 -> 0 | J24: =0 -> 0 | K24: =0 -> 0 | L24: =0 -> 0 | M24: =11.6 -> 11.6 | N24: =0 -> 0 | O24: =5.8 -> 5.8
B25: 46206 | C25: =9.8 -> 9.8 | D25: =0 -> 0 | E25: =0 -> 0 | F25: =0 -> 0 | G25: =0 -> 0 | H25: =0 -> 0 | I25: =0 -> 0 | J25: =0 -> 0 | K25: =0 -> 0 | L25: =0 -> 0 | M25: =39.2 -> 39.2 | N25: =0 -> 0 | O25: =0 -> 0
B26: 46206 | C26: =17 -> 17 | D26: =0 -> 0 | E26: =0 -> 0 | F26: =0 -> 0 | G26: =0 -> 0 | H26: =0 -> 0 | I26: =0 -> 0 | J26: =0 -> 0 | K26: =0 -> 0 | ... O26: =0 -> 0
B27: 46206 | C27: =28.8 -> 28.8 | D27: =0 -> 0 | E27: =0 -> 0 | F27: =0 -> 0 | G27: =0 -> 0 | H27: =0 -> 0 | I27: =0 -> 0 | J27: =0 -> 0 | K27: =0 -> 0 | L27: =115.2 -> 115.2 | M27: =0 -> 0 | N27: =0 -> 0 | O27: =0 -> 0
B28: 46206 | C28: =0 -> 0 | D28: =20.5 -> 20.5 | E28: =0 -> 0 | F28: =0 -> 0 | G28: =0 -> 0 | H28: =0 -> 0 | I28: =0 -> 0 | J28: =0 -> 0 | K28: =0 -> 0 | L28: =0 -> 0 | M28: =0 -> 0 | N28: =20.5 -> 20.5 | O28: =0 -> 0
B29: 46206 | C29: =19.5 -> 19.5 | D29: =0 -> 0 | E29: =0 -> 0 | F29: =0 -> 0 | G29: =0 -> 0 | H29: =0 -> 0 | I29: =19.5 -> 19.5 | J29: =0 -> 0 | K29: =0 -> 0 | L29: =0 -> 0 | M29: =0 -> 0 | N29: =0 -> 0 | O29: =0 -> 0
B30: 46206 | C30: =0 -> 0 | D30: =0 -> 0 | E30: =0 -> 0 | F30: =0 -> 0 | G30: =0 -> 0 | H30: =0 -> 0 | I30: =0 -> 0 | J30: =0 -> 0 | ... M30: =0 -> 0 | N30: =15 -> 15 | O30: =0 -> 0
B31: 46206 | C31: =0 -> 0 | D31: =0 -> 0 | E31: =0 -> 0 | F31: =0 -> 0 | G31: =20 -> 20 | H31: =0 -> 0 | I31: =0 -> 0 | J31: =0 -> 0 | K31: =0 -> 0 | L31: =0 -> 0 | M31: =0 -> 0 | N31: =0 -> 0 | O31: =0 -> 0
B32: 46206 | C32: =0 -> 0 | D32: =11.6 -> 11.6 | E32: =0 -> 0 | F32: =0 -> 0 | G32: =0 -> 0 | H32: =0 -> 0 | I32: =0 -> 0 | J32: =0 -> 0 | K32: =0 -> 0 | L32: =0 -> 0 | M32: =0 -> 0 | N32: =46.4 -> 46.4 | O32: =0 -> 0
B33: 46206 | C33: =0 -> 0 | D33: =0 -> 0 | E33: =10.1 -> 10.1 | F33: =0 -> 0 | G33: =0 -> 0 | H33: =0 -> 0 | I33: =50.5 -> 50.5 | J33: =0 -> 0 | K33: =0 -> 0 | L33: =0 -> 0 | M33: =0 -> 0 | N33: =40.4 -> 40.4 | O33: =0 -> 0
B34: 46206 | C34: =15.2 -> 15.2 | D34: =0 -> 0 | E34: =0 -> 0 | F34: =0 -> 0 | G34: =22.8 -> 22.8 | H34: =0 -> 0 | I34: =0 -> 0 | J34: =0 -> 0 | K34: =0 -> 0 | L34: =0 -> 0 | M34: =0 -> 0 | N34: =0 -> 0 | O34: =0 -> 0
B35: 46207 | C35: =59 -> 59 | D35: =35.4 -> 35.4 | E35: =0 -> 0 | F35: =0 -> 0 | G35: =0 -> 0 | H35: =0 -> 0 | I35: =23.6 -> 23.6 | J35: =0 -> 0 | K35: =0 -> 0 | L35: =0 -> 0 | M35: =0 -> 0 | N35: =0 -> 0 | O35: =0 -> 0
B36: 46207 | C36: 0 | D36: 0 | E36: 0 | F36: 0 | G36: 0 | H36: 0 | I36: 0 | J36: 0 | K36: 0 | L36: 0 | M36: 0 | N36: 0 | O36: =132 -> 132
B37: 46207 | C37: =0 -> 0 | D37: =0 -> 0 | E37: =0 -> 0 | F37: =0 -> 0 | G37: =0 -> 0 | H37: =0 -> 0 | I37: =0 -> 0 | J37: =686 -> 686 | K37: =0 -> 0 | L37: =0 -> 0 | M37: =0 -> 0 | N37: =0 -> 0 | O37: =0 -> 0
B38: 46207 | C38: 0 | D38: 0 | E38: 0 | F38: 0 | G38: 0 | H38: 0 | I38: 0 | J38: 0 | K38: 0 | L38: 0 | M38: 0 | N38: 0 | O38: =6 -> 6
B39: 46207 | C39: =0 -> 0 | D39: =0 -> 0 | E39: =0 -> 0 | F39: =0 -> 0 | G39: =0 -> 0 | H39: =0 -> 0 | I39: =64.8 -> 64.8 | J39: =0 -> 0 | K39: =0 -> 0 | L39: =43.2 -> 43.2 | M39: =0 -> 0 | N39: =0 -> 0 | O39: =0 -> 0
B40: 46207 | C40: =24.8 -> 24.8 | D40: =0 -> 0 | E40: =0 -> 0 | F40: =0 -> 0 | G40: =0 -> 0 | H40: =0 -> 0 | I40: =12.4 -> 12.4 | J40: =24.8 -> 24.8 | K40: =0 -> 0 | L40: =0 -> 0 | M40: =12.4 -> 12.4 | N40: =24.8 -> 24.8 | O40: =24.8 -> 24.8
...

Sheet CollTubList
B1: Date | C1: Iron and steel | D1: Aluminium | E1: Other non-ferrous | F1: Mixed metals | G1: Textiles | H1: Mattresses | I1: Timber | J1: Bricks | K1: Demolition | L1: Paper and cardboard | M1: Plastics | N1: Glass | O1: Mixed materials
B2: 46205 | C2: 0 | D2: 0 | E2: 0 | F2: 0 | G2: 0 | H2: 0 | I2: 0 | J2: 0 | K2: 0 | L2: 0 | M2: 0 | N2: 0 | O2: =15 -> 15
B3: 46205 | C3: 0 | D3: 0 | E3: 0 | F3: 0 | G3: 0 | H3: 0 | I3: 0 | J3: 0 | K3: 0 | L3: 0 | M3: 0 | N3: 0 | O3: =37 -> 37
B4: 46206 | C4: 0 | D4: 0 | E4: 0 | F4: 0 | G4: 0 | H4: 0 | I4: 0 | J4: 0 | K4: 0 | L4: 0 | M4: 0 | N4: 0 | O4: =17 -> 17
B5: 46206 | C5: =0 -> 0 | D5: =0 -> 0 | E5: =0 -> 0 | F5: =2.8 -> 2.8 | G5: =0 -> 0 | H5: =0 -> 0 | I5: =0 -> 0 | J5: =0 -> 0 | K5: =0 -> 0 | L5: =0 -> 0 | M5: =0 -> 0 | N5: =4.2 -> 4.2 | O5: =7 -> 7
B6: 46207 | C6: =0 -> 0 | D6: =2.4 -> 2.4 | E6: =0 -> 0 | F6: =0 -> 0 | G6: =0 -> 0 | H6: =0 -> 0 | I6: =2.4 -> 2.4 | J6: =0 -> 0 | K6: =0 -> 0 | L6: =0 -> 0 | M6: =0 -> 0 | N6: =2.4 -> 2.4 | O6: =4.8 -> 4.8
B7: 46209 | C7: =0 -> 0 | D7: =0 -> 0 | E7: =0 -> 0 | F7: =0 -> 0 | G7: =0 -> 0 | H7: =0 -> 0 | I7: =0 -> 0 | J7: =0 -> 0 | ... M7: =0 -> 0 | N7: =12 -> 12 | O7: =12 -> 12
B8: 46210 | C8: =1 -> 1 | D8: =0 -> 0 | E8: =0 -> 0 | F8: =0 -> 0 | G8: =0 -> 0 | H8: =0 -> 0 | I8: =0 -> 0 | J8: =0 -> 0 | K8: =0 -> 0 | ... M8: =0 -> 0 | N8: =1 -> 1 | O8: =8 -> 8
B9: 46210 | C9: 0 | D9: 0 | E9: 0 | F9: 0 | G9: 0 | H9: 0 | I9: 0 | J9: 0 | K9: 0 | L9: 0 | M9: 0 | N9: 0 | O9: =14 -> 14
B10: 46212 | C10: =0 -> 0 | D10: =0 -> 0 | E10: =0 -> 0 | F10: =4 -> 4 | G10: =0 -> 0 | H10: =0 -> 0 | I10: =0 -> 0 | J10: =0 -> 0 | K10: =0 -> 0 | L10: =4 -> 4 | M10: =0 -> 0 | N10: =4 -> 4 | O10: =4 -> 4
B11: 46213 | C11: =2.1 -> 2.1 | D11: =0 -> 0 | E11: =0 -> 0 | F11: =0 -> 0 | G11: =0 -> 0 | H11: =0 -> 0 | I11: =0 -> 0 | J11: =0 -> 0 | K11: =0 -> 0 | ... M11: =0 -> 0 | N11: =6.3 -> 6.3 | O11: =12.6 -> 12.6
B12: 46213 | C12: =5.1 -> 5.1 | D12: =0 -> 0 | E12: =0 -> 0 | F12: =0 -> 0 | G12: =0 -> 0 | H12: =0 -> 0 | I12: =0 -> 0 | J12: =0 -> 0 | K12: =0 -> 0 | ... M12: =0 -> 0 | N12: =5.1 -> 5.1 | O12: =6.8 -> 6.8
B13: 46213 | C13: =0 -> 0 | D13: =0 -> 0 | E13: =0 -> 0 | F13: =0 -> 0 | G13: =0 -> 0 | H13: =0 -> 0 | I13: =0 -> 0 | J13: =0 -> 0 | K13: =0 -> 0 | L13: =8.4 -> 8.4 | M13: =0 -> 0 | N13: =5.6 -> 5.6 | O13: =14 -> 14
B14: 46213 | C14: =3.2 -> 3.2 | D14: =0 -> 0 | E14: =0 -> 0 | F14: =0 -> 0 | G14: =0 -> 0 | H14: =0 -> 0 | I14: =0 -> 0 | J14: =0 -> 0 | K14: =0 -> 0 | ... M14: =0 -> 0 | N14: =4.8 -> 4.8 | O14: =8 -> 8
B15: 46214 | C15: =0 -> 0 | D15: =0 -> 0 | E15: =0 -> 0 | F15: =3.6 -> 3.6 | G15: =7.2 -> 7.2 | H15: =0 -> 0 | I15: =0 -> 0 | J15: =0 -> 0 | K15: =0 -> 0 | L15: =0 -> 0 | M15: =3.6 -> 3.6 | N15: =0 -> 0 | O15: =3.6 -> 3.6
B16: 46215 | C16: =0 -> 0 | D16: =0 -> 0 | E16: =0 -> 0 | F16: =0 -> 0 | G16: =5.7 -> 5.7 | H16: =0 -> 0 | I16: =0 -> 0 | J16: =0 -> 0 | K16: =0 -> 0 | L16: =3.8 -> 3.8 | M16: =1.9 -> 1.9 | N16: =0 -> 0 | O16: =7.6 -> 7.6
B17: 46218 | C17: =0 -> 0 | D17: =0 -> 0 | E17: =0 -> 0 | F17: =0 -> 0 | G17: =0 -> 0 | H17: =0 -> 0 | I17: =4.2 -> 4.2 | J17: =0 -> 0 | K17: =0 -> 0 | L17: =0 -> 0 | M17: =0 -> 0 | N17: =4.2 -> 4.2 | O17: =5.6 -> 5.6
B18: 46218 | C18: =12.6 -> 12.6 | D18: =0 -> 0 | E18: =0 -> 0 | F18: =0 -> 0 | G18: =0 -> 0 | H18: =0 -> 0 | I18: =0 -> 0 | J18: =0 -> 0 | K18: =0 -> 0 | ... M18: =0 -> 0 | N18: =4.2 -> 4.2 | O18: =4.2 -> 4.2
B19: 46218 | C19: =21.6 -> 21.6 | D19: =0 -> 0 | E19: =0 -> 0 | F19: =0 -> 0 | G19: =0 -> 0 | H19: =0 -> 0 | I19: =0 -> 0 | J19: =0 -> 0 | K19: =0 -> 0 | ... M19: =0 -> 0 | N19: =2.7 -> 2.7 | O19: =2.7 -> 2.7
B20: 46218 | C20: =8.8 -> 8.8 | D20: =0 -> 0 | E20: =0 -> 0 | F20: =0 -> 0 | G20: =0 -> 0 | H20: =0 -> 0 | I20: =0 -> 0 | J20: =0 -> 0 | K20: =0 -> 0 | ... M20: =0 -> 0 | N20: =8.8 -> 8.8 | O20: =4.4 -> 4.4
B21: 46219 | C21: =0 -> 0 | D21: =0 -> 0 | E21: =0 -> 0 | F21: =2.8 -> 2.8 | G21: =0 -> 0 | H21: =0 -> 0 | I21: =5.6 -> 5.6 | J21: =0 -> 0 | K21: =0 -> 0 | L21: =0 -> 0 | M21: =2.8 -> 2.8 | N21: =0 -> 0 | O21: =2.8 -> 2.8
B22: 46222 | C22: =0 -> 0 | D22: =0 -> 0 | E22: =0 -> 0 | F22: =0 -> 0 | G22: =3 -> 3 | H22: =0 -> 0 | I22: =1.2 -> 1.2 | J22: =0 -> 0 | K22: =0 -> 0 | L22: =0 -> 0 | M22: =3 -> 3 | N22: =1.8 -> 1.8 | O22: =3 -> 3
B23: 46222 | C23: =0 -> 0 | D23: =0 -> 0 | E23: =0 -> 0 | F23: =0 -> 0 | G23: =4.5 -> 4.5 | H23: =0 -> 0 | I23: =0 -> 0 | J23: =0 -> 0 | K23: =0 -> 0 | L23: =4.5 -> 4.5 | M23: =0 -> 0 | N23: =0 -> 0 | O23: =9 -> 9
B24: 46222 | C24: =0 -> 0 | D24: =0 -> 0 | E24: =0 -> 0 | F24: =2.1 -> 2.1 | G24: =0 -> 0 | H24: =0 -> 0 | I24: =3.15 -> 3.15 | J24: =0 -> 0 | K24: =0 -> 0 | L24: =5.25 -> 5.25 | M24: =0 -> 0 | N24: =0 -> 0 | O24: =10.5 -> 10.5
B25: 46224 | C25: =3.6 -> 3.6 | D25: =0 -> 0 | E25: =0 -> 0 | F25: =0 -> 0 | G25: =0 -> 0 | H25: =0 -> 0 | I25: =0 -> 0 | J25: =0 -> 0 | K25: =0 -> 0 | L25: =0 -> 0 | M25: =3.6 -> 3.6 | N25: =0 -> 0 | O25: =4.8 -> 4.8
B26: 46225 | C26: =3.8 -> 3.8 | D26: =0 -> 0 | E26: =0 -> 0 | F26: =0 -> 0 | G26: =0 -> 0 | H26: =0 -> 0 | I26: =1.9 -> 1.9 | J26: =0 -> 0 | K26: =0 -> 0 | L26: =0 -> 0 | M26: =0 -> 0 | N26: =5.7 -> 5.7 | O26: =7.6 -> 7.6
B27: 46225 | C27: =0 -> 0 | D27: =0 -> 0 | E27: =0 -> 0 | F27: =0 -> 0 | G27: =0 -> 0 | H27: =0 -> 0 | I27: =6.4 -> 6.4 | J27: =0 -> 0 | K27: =0 -> 0 | L27: =0 -> 0 | M27: =0 -> 0 | N27: =6.4 -> 6.4 | O27: =3.2 -> 3.2
B28: 46225 | C28: =2.8 -> 2.8 | D28: =0 -> 0 | E28: =0 -> 0 | F28: =0 -> 0 | G28: =0 -> 0 | H28: =0 -> 0 | I28: =0 -> 0 | J28: =0 -> 0 | K28: =0 -> 0 | ... M28: =0 -> 0 | N28: =5.6 -> 5.6 | O28: =5.6 -> 5.6
B29: 46228 | C29: =1.9 -> 1.9 | D29: =3.8 -> 3.8 | E29: =0 -> 0 | F29: =0 -> 0 | G29: =0 -> 0 | H29: =0 -> 0 | I29: =1.9 -> 1.9 | J29: =0 -> 0 | K29: =0 -> 0 | L29: =0 -> 0 | M29: =5.7 -> 5.7 | N29: =0 -> 0 | O29: =5.7 -> 5.7
B30: 46228 | C30: =0 -> 0 | D30: =1.5 -> 1.5 | E30: =0 -> 0 | F30: =0 -> 0 | G30: =2.25 -> 2.25 | H30: =0 -> 0 | I30: =0 -> 0 | J30: =0 -> 0 | K30: =0 -> 0 | L30: =3.75 -> 3.75 | M30: =3.75 -> 3.75 | N30: =0 -> 0 | O30: =3.75 -> 3.75
B31: 46228 | C31: =0 -> 0 | D31: =0 -> 0 | E31: =0 -> 0 | F31: =0 -> 0 | G31: =7 -> 7 | H31: =0 -> 0 | I31: =0 -> 0 | J31: =0 -> 0 | K31: =0 -> 0 | L31: =7 -> 7 | M31: =0 -> 0 | N31: =0 -> 0 | O31: =14 -> 14
B32: 46231 | C32: 0 | D32: 0 | E32: 0 | F32: 0 | G32: 0 | H32: 0 | I32: 0 | J32: 0 | K32: 0 | L32: 0 | M32: 0 | N32: 0 | O32: =9 -> 9
B33: 46231 | C33: 0 | D33: 0 | E33: 0 | F33: 0 | G33: 0 | H33: 0 | I33: 0 | J33: 0 | K33: 0 | L33: 0 | M33: 0 | N33: 0 | O33: =15 -> 15
B34: 46231 | C34: =13.2 -> 13.2 | D34: =0 -> 0 | E34: =0 -> 0 | F34: =0 -> 0 | G34: =0 -> 0 | H34: =0 -> 0 | I34: =0 -> 0 | J34: =0 -> 0 | K34: =0 -> 0 | ... N34: =0 -> 0 | O34: =8.8 -> 8.8
B35: 46231 | C35: =9.6 -> 9.6 | D35: =0 -> 0 | E35: =0 -> 0 | F35: =0 -> 0 | G35: =0 -> 0 | H35: =0 -> 0 | I35: =0 -> 0 | J35: =0 -> 0 | K35: =0 -> 0 | ... M35: =0 -> 0 | N35: =2.4 -> 2.4 | O35: =0 -> 0
B36: 46231 | C36: =5.4 -> 5.4 | D36: =0 -> 0 | E36: =0 -> 0 | F36: =0 -> 0 | G36: =0 -> 0 | H36: =0 -> 0 | I36: =0 -> 0 | J36: =0 -> 0 | K36: =0 -> 0 | ... N36: =0 -> 0 | O36: =12.6 -> 12.6
B37: 46233 | C37: 0 | D37: 0 | E37: 0 | F37: 0 | G37: 0 | H37: 0 | I37: 0 | J37: 0 | K37: 0 | L37: 0 | M37: 0 | N37: 0 | O37: =22 -> 22
B38: 46233 | C38: =0 -> 0 | D38: =0 -> 0 | E38: =0 -> 0 | F38: =0 -> 0 | G38: =0 -> 0 | H38: =0 -> 0 | I38: =0 -> 0 | J38: =0 -> 0 | ... M38: =0 -> 0 | N38: =7.2 -> 7.2 | O38: =10.8 -> 10.8
B39: 46234 | C39: =0 -> 0 | D39: =0 -> 0 | E39: =0 -> 0 | F39: =0 -> 0 | G39: =0 -> 0 | H39: =0 -> 0 | I39: =0 -> 0 | J39: =0 -> 0 | ... L39: =0 -> 0 | M39: =8.4 -> 8.4 | N39: =0 -> 0 | O39: =5.6 -> 5.6
B40: 46237 | C40: 0 | D40: 0 | E40: 0 | F40: 0 | G40: 0 | H40: 0 | I40: 0 | J40: 0 | K40: 0 | L40: 0 | M40: 0 | N40: 0 | O40: =16 -> 16
...

Sheet PickupList
B1: Date | C1: Iron and steel | D1: Aluminium | E1: Other non-ferrous | F1: Mixed metals | G1: Textiles | H1: Mattresses | I1: Timber | J1: Bricks | K1: Building & Demolition | L1: Paper and cardboard | M1: Plastics | N1: Glass | O1: Mixed materials
B2: 46205 | C2: =100 -> 100 | D2: =0 -> 0 | E2: =0 -> 0 | F2: =0 -> 0 | G2: =0 -> 0 | H2: =0 -> 0 | I2: =0 -> 0 | J2: =0 -> 0 | K2: =0 -> 0 | ... O2: =0 -> 0
B3: 46205 | C3: =400 -> 400 | D3: =0 -> 0 | E3: =0 -> 0 | F3: =0 -> 0 | G3: =0 -> 0 | H3: =0 -> 0 | I3: =0 -> 0 | J3: =0 -> 0 | K3: =0 -> 0 | ... O3: =0 -> 0
B4: 46209 | C4: =0 -> 0 | D4: =0 -> 0 | E4: =0 -> 0 | F4: =0 -> 0 | G4: =63 -> 63 | H4: =0 -> 0 | I4: =7 -> 7 | J4: =0 -> 0 | K4: =0 -> 0 | L4: =0 -> 0 | M4: =0 -> 0 | N4: =0 -> 0 | O4: =0 -> 0
B5: 46209 | C5: =0 -> 0 | D5: =0 -> 0 | E5: =0 -> 0 | F5: =0 -> 0 | G5: =0 -> 0 | H5: =0 -> 0 | I5: =90 -> 90 | J5: =0 -> 0 | K5: =0 -> 0 | L5: =0 -> 0 | M5: =10 -> 10 | N5: =0 -> 0 | O5: =0 -> 0
B6: 46209 | C6: 0 | D6: 0 | E6: 0 | F6: 0 | G6: 0 | H6: 0 | I6: =40 -> 40 | J6: 0 | K6: 0 | L6: 0 | M6: 0 | N6: 0 | O6: 0
B7: 46216 | C7: =0 -> 0 | D7: =0 -> 0 | E7: =0 -> 0 | F7: =0 -> 0 | G7: =0 -> 0 | H7: =0 -> 0 | I7: =0 -> 0 | J7: =0 -> 0 | ... L7: =0 -> 0 | M7: =100 -> 100 | N7: =0 -> 0 | O7: =0 -> 0
B8: 46216 | C8: =100 -> 100 | D8: =0 -> 0 | E8: =0 -> 0 | F8: =0 -> 0 | G8: =0 -> 0 | H8: =0 -> 0 | I8: =0 -> 0 | J8: =0 -> 0 | K8: =0 -> 0 | ... O8: =0 -> 0
B9: 46216 | C9: =0 -> 0 | D9: =0 -> 0 | E9: =0 -> 0 | F9: =0 -> 0 | G9: =0 -> 0 | H9: =40 -> 40 | I9: =0 -> 0 | J9: =0 -> 0 | K9: =0 -> 0 | L9: =0 -> 0 | M9: =0 -> 0 | N9: =0 -> 0 | O9: =0 -> 0
B10: 46223 | C10: =0 -> 0 | D10: =0 -> 0 | E10: =0 -> 0 | F10: =0 -> 0 | G10: =0 -> 0 | H10: =0 -> 0 | I10: =0 -> 0 | J10: =0 -> 0 | ... L10: =0 -> 0 | M10: =60 -> 60 | N10: =0 -> 0 | O10: =0 -> 0
B11: 46223 | C11: 0 | D11: 0 | E11: 0 | F11: 0 | G11: 0 | H11: 0 | I11: =50 -> 50 | J11: 0 | K11: 0 | L11: 0 | M11: 0 | N11: 0 | O11: 0
B12: 46226 | C12: =150 -> 150 | D12: =0 -> 0 | E12: =0 -> 0 | F12: =0 -> 0 | G12: =0 -> 0 | H12: =0 -> 0 | I12: =0 -> 0 | J12: =0 -> 0 | K12: =0 -> 0 | ... O12: =0 -> 0
B13: 46226 | C13: =60 -> 60 | D13: =0 -> 0 | E13: =0 -> 0 | F13: =0 -> 0 | G13: =0 -> 0 | H13: =0 -> 0 | I13: =240 -> 240 | J13: =0 -> 0 | K13: =0 -> 0 | L13: =0 -> 0 | M13: =0 -> 0 | N13: =0 -> 0 | O13: =0 -> 0
B14: 46233 | C14: =800 -> 800 | D14: =0 -> 0 | E14: =0 -> 0 | F14: =0 -> 0 | G14: =0 -> 0 | H14: =0 -> 0 | I14: =0 -> 0 | J14: =0 -> 0 | K14: =0 -> 0 | ... O14: =0 -> 0
B15: 46233 | C15: 0 | D15: 0 | E15: 0 | F15: 0 | G15: 0 | H15: 0 | I15: =200 -> 200 | J15: 0 | K15: 0 | L15: 0 | M15: 0 | N15: 0 | O15: 0
B16: 46237 | C16: =180 -> 180 | D16: =0 -> 0 | E16: =0 -> 0 | F16: =0 -> 0 | G16: =0 -> 0 | H16: =0 -> 0 | I16: =0 -> 0 | J16: =0 -> 0 | K16: =0 -> 0 | ... O16: =0 -> 0
B17: 46237 | C17: =0 -> 0 | D17: =0 -> 0 | E17: =0 -> 0 | F17: =0 -> 0 | G17: =0 -> 0 | H17: =0 -> 0 | I17: =0 -> 0 | J17: =0 -> 0 | ... N17: =0 -> 0 | O17: =650 -> 650
B18: 46239 | C18: =135 -> 135 | D18: =0 -> 0 | E18: =0 -> 0 | F18: =0 -> 0 | G18: =0 -> 0 | H18: =0 -> 0 | I18: =0 -> 0 | J18: =0 -> 0 | K18: =0 -> 0 | L18: =0 -> 0 | M18: =15 -> 15 | N18: =0 -> 0 | O18: =0 -> 0
B19: 46244 | C19: =50 -> 50 | D19: =0 -> 0 | E19: =0 -> 0 | F19: =0 -> 0 | G19: =0 -> 0 | H19: =0 -> 0 | I19: =0 -> 0 | J19: =0 -> 0 | K19: =0 -> 0 | ... O19: =0 -> 0
B20: 46251 | C20: =9 -> 9 | D20: =0 -> 0 | E20: =0 -> 0 | F20: =0 -> 0 | G20: =18 -> 18 | H20: =0 -> 0 | I20: =0 -> 0 | J20: =0 -> 0 | K20: =0 -> 0 | L20: =0 -> 0 | M20: =0 -> 0 | N20: =0 -> 0 | O20: =3 -> 3
B21: 46251 | C21: =0 -> 0 | D21: =0 -> 0 | E21: =0 -> 0 | F21: =0 -> 0 | G21: =0 -> 0 | H21: =0 -> 0 | I21: =30 -> 30 | J21: =0 -> 0 | K21: =10 -> 10 | L21: =0 -> 0 | M21: =0 -> 0 | N21: =60 -> 60 | O21: =0 -> 0
B22: 46251 | C22: =0 -> 0 | D22: =0 -> 0 | E22: =0 -> 0 | F22: =0 -> 0 | G22: =0 -> 0 | H22: =80 -> 80 | I22: =0 -> 0 | J22: =0 -> 0 | K22: =0 -> 0 | L22: =0 -> 0 | M22: =0 -> 0 | N22: =0 -> 0 | O22: =0 -> 0
B23: 46254 | C23: =0 -> 0 | D23: =0 -> 0 | E23: =0 -> 0 | F23: =0 -> 0 | G23: =0 -> 0 | H23: =200 -> 200 | I23: =0 -> 0 | J23: =0 -> 0 | K23: =0 -> 0 | L23: =0 -> 0 | M23: =0 -> 0 | N23: =0 -> 0 | O23: =0 -> 0
B24: 46254 | C24: =100 -> 100 | D24: =0 -> 0 | E24: =0 -> 0 | F24: =0 -> 0 | G24: =0 -> 0 | H24: =0 -> 0 | I24: =0 -> 0 | J24: =0 -> 0 | K24: =0 -> 0 | ... O24: =0 -> 0
B25: 46265 | C25: =126 -> 126 | D25: =0 -> 0 | E25: =14 -> 14 | F25: =0 -> 0 | G25: =0 -> 0 | H25: =0 -> 0 | I25: =0 -> 0 | J25: =0 -> 0 | K25: =0 -> 0 | L25: =0 -> 0 | M25: =0 -> 0 | ... O25: =0 -> 0
B26: 46265 | C26: =12 -> 12 | D26: =0 -> 0 | E26: =0 -> 0 | F26: =0 -> 0 | G26: =12 -> 12 | H26: =0 -> 0 | I26: =84 -> 84 | J26: =0 -> 0 | K26: =0 -> 0 | L26: =0 -> 0 | M26: =0 -> 0 | N26: =0 -> 0 | O26: =12 -> 12
B27: 46265 | C27: =15 -> 15 | D27: =0 -> 0 | E27: =0 -> 0 | F27: =0 -> 0 | G27: =0 -> 0 | H27: =0 -> 0 | I27: =15 -> 15 | J27: =0 -> 0 | K27: =0 -> 0 | L27: =0 -> 0 | M27: =0 -> 0 | N27: =0 -> 0 | O27: =0 -> 0
B28: 46265 | C28: =0 -> 0 | D28: =30 -> 30 | E28: =0 -> 0 | F28: =0 -> 0 | G28: =0 -> 0 | H28: =0 -> 0 | I28: =0 -> 0 | J28: =0 -> 0 | K28: =0 -> 0 | L28: =0 -> 0 | M28: =0 -> 0 | N28: =270 -> 270 | O28: =0 -> 0
B29: 46265 | C29: =40 -> 40 | D29: =0 -> 0 | E29: =0 -> 0 | F29: =0 -> 0 | G29: =0 -> 0 | H29: =0 -> 0 | I29: =0 -> 0 | J29: =0 -> 0 | K29: =0 -> 0 | ... O29: =0 -> 0
B30: 46272 | C30: =120 -> 120 | D30: =0 -> 0 | E30: =0 -> 0 | F30: =0 -> 0 | G30: =80 -> 80 | H30: =0 -> 0 | I30: =80 -> 80 | J30: =0 -> 0 | K30: =0 -> 0 | L30: =0 -> 0 | M30: =80 -> 80 | N30: =0 -> 0 | O30: =40 -> 40
B31: 46272 | C31: =320 -> 320 | D31: =0 -> 0 | E31: =0 -> 0 | F31: =0 -> 0 | G31: =0 -> 0 | H31: =0 -> 0 | I31: =480 -> 480 | J31: =0 -> 0 | K31: =0 -> 0 | L31: =0 -> 0 | M31: =0 -> 0 | N31: =0 -> 0 | O31: =0 -> 0
B32: 46275 | C32: =180 -> 180 | D32: =0 -> 0 | E32: =0 -> 0 | F32: =60 -> 60 | G32: =0 -> 0 | H32: =0 -> 0 | I32: =120 -> 120 | J32: =0 -> 0 | K32: =0 -> 0 | L32: =0 -> 0 | M32: =0 -> 0 | N32: =180 -> 180 | O32: =60 -> 60
B33: 46275 | C33: =140 -> 140 | D33: =20 -> 20 | E33: =40 -> 40 | F33: =0 -> 0 | G33: =0 -> 0 | H33: =0 -> 0 | I33: =0 -> 0 | J33: =0 -> 0 | K33: =0 -> 0 | L33: =0 -> 0 | M33: =0 -> 0 | ... O33: =0 -> 0
B34: 46279 | C34: =240 -> 240 | D34: =0 -> 0 | E34: =0 -> 0 | F34: =0 -> 0 | G34: =0 -> 0 | H34: =0 -> 0 | I34: =360 -> 360 | J34: =0 -> 0 | K34: =0 -> 0 | L34: =0 -> 0 | M34: =0 -> 0 | N34: =0 -> 0 | O34: =0 -> 0
B35: 46279 | C35: =60 -> 60 | D35: =0 -> 0 | E35: =0 -> 0 | F35: =0 -> 0 | G35: =0 -> 0 | H35: =0 -> 0 | I35: =60 -> 60 | J35: =0 -> 0 | K35: =0 -> 0 | L35: =0 -> 0 | M35: =40 -> 40 | N35: =0 -> 0 | O35: =40 -> 40
B36: 46282 | C36: =200 -> 200 | D36: =0 -> 0 | E36: =0 -> 0 | F36: =0 -> 0 | G36: =0 -> 0 | H36: =0 -> 0 | I36: =0 -> 0 | J36: =0 -> 0 | K36: =0 -> 0 | ... O36: =0 -> 0
B37: 46286 | C37: =9 -> 9 | D37: =0 -> 0 | E37: =0 -> 0 | F37: =0 -> 0 | G37: =0 -> 0 | H37: =0 -> 0 | I37: =81 -> 81 | J37: =0 -> 0 | K37: =0 -> 0 | L37: =0 -> 0 | M37: =0 -> 0 | N37: =0 -> 0 | O37: =0 -> 0
B38: 46286 | C38: =0 -> 0 | D38: =0 -> 0 | E38: =0 -> 0 | F38: =0 -> 0 | G38: =0 -> 0 | H38: =0 -> 0 | I38: =27 -> 27 | J38: =0 -> 0 | K38: =0 -> 0 | L38: =0 -> 0 | M38: =0 -> 0 | N38: =3 -> 3 | O38: =0 -> 0
B39: 46286 | C39: =120 -> 120 | D39: =0 -> 0 | E39: =0 -> 0 | F39: =0 -> 0 | G39: =0 -> 0 | H39: =0 -> 0 | I39: =200 -> 200 | J39: =0 -> 0 | K39: =0 -> 0 | L39: =0 -> 0 | M39: =0 -> 0 | N39: =0 -> 0 | O39: =80 -> 80
B40: 46286 | C40: =30 -> 30 | D40: =0 -> 0 | E40: =0 -> 0 | F40: =0 -> 0 | G40: =30 -> 30 | H40: =0 -> 0 | I40: =0 -> 0 | J40: =0 -> 0 | K40: =0 -> 0 | L40: =0 -> 0 | M40: =45 -> 45 | N40: =30 -> 30 | O40: =15 -> 15
...

Sheet ElecCrateList
B1: Date | C1: Ewaste (TVs etc) | D1: Mixed Materials
B2: 46204 | C2: =0 -> 0 | D2: =97 -> 97
B3: 46205 | C3: =0 -> 0 | D3: =157 -> 157
B4: 46209 | C4: =0 -> 0 | D4: =103 -> 103
B5: 46209 | C5: =5.3 -> 5.3 | D5: =100.7 -> 100.7
B6: 46209 | C6: =0 -> 0 | D6: =155 -> 155
B7: 46210 | C7: =0 -> 0 | D7: =143 -> 143
B8: 46211 | C8: =13.9 -> 13.9 | D8: =125.1 -> 125.1
B9: 46211 | C9: =8.5 -> 8.5 | D9: =161.5 -> 161.5
B10: 46213 | C10: =0 -> 0 | D10: =102 -> 102
B11: 46218 | C11: =7.35 -> 7.35 | D11: =139.65 -> 139.65
B12: 46218 | C12: =0 -> 0 | D12: =154 -> 154
B13: 46220 | C13: =0 -> 0 | D13: =134 -> 134
B14: 46222 | C14: =140 -> 140 | D14: =0 -> 0
B15: 46222 | C15: =8.2 -> 8.2 | D15: =155.8 -> 155.8
B16: 46225 | C16: =7.9 -> 7.9 | D16: =150.1 -> 150.1
B17: 46225 | C17: =0 -> 0 | D17: =118 -> 118
B18: 46226 | C18: =0 -> 0 | D18: =112 -> 112
B19: 46231 | C19: =0 -> 0 | D19: =149 -> 149
B20: 46233 | C20: =0 -> 0 | D20: =114 -> 114
B21: 46233 | C21: =0 -> 0 | D21: =157 -> 157
B22: 46238 | C22: =0 -> 0 | D22: =116 -> 116
B23: 46239 | C23: =18.9 -> 18.9 | D23: =107.1 -> 107.1
B24: 46240 | C24: =0 -> 0 | D24: =127 -> 127
B25: 46241 | C25: =0 -> 0 | D25: =73 -> 73
B26: 46241 | C26: =0 -> 0 | D26: =103 -> 103
B27: 46244 | C27: =0 -> 0 | D27: =135 -> 135
B28: 46246 | C28: =0 -> 0 | D28: =139 -> 139
B29: 46248 | C29: =0 -> 0 | D29: =108 -> 108
B30: 46248 | C30: =0 -> 0 | D30: =124 -> 124
B31: 46254 | C31: =0 -> 0 | D31: =99 -> 99
B32: 46254 | C32: =0 -> 0 | D32: =120 -> 120
B33: 46258 | C33: =78.3 -> 78.3 | D33: =8.7 -> 8.7
B34: 46261 | C34: =0 -> 0 | D34: =143 -> 143
B35: 46261 | C35: =0 -> 0 | D35: =103 -> 103
B36: 46262 | C36: =0 -> 0 | D36: =114 -> 114
B37: 46266 | C37: =9 -> 9 | D37: =81 -> 81
B38: 46266 | C38: =5.65 -> 5.65 | D38: =107.35 -> 107.35
B39: 46266 | C39: =0 -> 0 | D39: =152 -> 152
B40: 46269 | C40: =7.15 -> 7.15 | D40: =135.85 -> 135.85
...

Sheet ElecPalletList
B1: Date | C1: Ewaste (TVs etc) | D1: Mixed Materials
B2: 46204 | C2: =36 -> 36 | D2: =84 -> 84
B3: 46204 | C3: =0 -> 0 | D3: =46 -> 46
B4: 46204 | C4: =0 -> 0 | D4: =103 -> 103
B5: 46204 | C5: =0 -> 0 | D5: =182 -> 182
B6: 46204 | C6: =85 -> 85 | D6: =0 -> 0
B7: 46206 | C7: =0 -> 0 | D7: =224 -> 224
B8: 46209 | C8: =57.5 -> 57.5 | D8: =57.5 -> 57.5
B9: 46209 | C9: =0 -> 0 | D9: =166 -> 166
B10: 46210 | C10: =26.2 -> 26.2 | D10: =104.8 -> 104.8
B11: 46213 | C11: =0 -> 0 | D11: =68 -> 68
B12: 46213 | C12: =0 -> 0 | D12: =119 -> 119
B13: 46217 | C13: =0 -> 0 | D13: =33 -> 33
B14: 46220 | C14: =70 -> 70 | D14: =0 -> 0
B15: 46222 | C15: =25.8 -> 25.8 | D15: =60.2 -> 60.2
B16: 46222 | C16: =82.6 -> 82.6 | D16: =35.4 -> 35.4
B17: 46222 | C17: =42.8 -> 42.8 | D17: =64.2 -> 64.2
B18: 46222 | C18: =11.8 -> 11.8 | D18: =106.2 -> 106.2
B19: 46222 | C19: =36.9 -> 36.9 | D19: =86.1 -> 86.1
B20: 46224 | C20: =113 -> 113 | D20: =0 -> 0
B21: 46224 | C21: =25 -> 25 | D21: =25 -> 25
B22: 46227 | C22: =16.2 -> 16.2 | D22: =91.8 -> 91.8
B23: 46227 | C23: =3.5 -> 3.5 | D23: =66.5 -> 66.5
B24: 46227 | C24: =54 -> 54 | D24: =54 -> 54
B25: 46234 | C25: =9 -> 9 | D25: =36 -> 36
B26: 46238 | C26: =11.3 -> 11.3 | D26: =101.7 -> 101.7
B27: 46238 | C27: =0 -> 0 | D27: =114 -> 114
B28: 46238 | C28: =23 -> 23 | D28: =69 -> 69
B29: 46238 | C29: =31.5 -> 31.5 | D29: =94.5 -> 94.5
B30: 46238 | C30: =11.6 -> 11.6 | D30: =104.4 -> 104.4
B31: 46238 | C31: =4.35 -> 4.35 | D31: =82.65 -> 82.65
B32: 46238 | C32: =10.2 -> 10.2 | D32: =40.8 -> 40.8
B33: 46238 | C33: =0 -> 0 | D33: =59 -> 59
B34: 46238 | C34: =0 -> 0 | D34: =73 -> 73
B35: 46241 | C35: =0 -> 0 | D35: =28 -> 28
B36: 46241 | C36: =106.4 -> 106.4 | D36: =45.6 -> 45.6
B37: 46241 | C37: =0 -> 0 | D37: =86 -> 86
B38: 46241 | C38: =41.2 -> 41.2 | D38: =61.8 -> 61.8
B39: 46241 | C39: =79.5 -> 79.5 | D39: =79.5 -> 79.5
B40: 46244 | C40: =0 -> 0 | D40: =134 -> 134
...

Sheet Whitegoods
B2: July | C2: 10
B3: August | C3: 15
B4: September | C4: 20
B5: October
B6: November
B7: December
B8: January
B9: February
B10: March
B11: April
B12: May
B13: June

Sheet Scrap
C3: Iron and steel | D3: Aluminium | E3: Other Non-Ferrous | F3: Mixed Metals | G3: Ewaste
B4: July | C4: 1920 | D4: 310 | E4: 989 | F4: 191 | G4: 1928
B5: August | C5: 0 | D5: 532 | E5: 529 | F5: 0 | G5: 655
B6: September | C6: 0 | D6: 0 | E6: 0 | F6: 0 | G6: 477
B7: October
B8: November
B9: December
B10: January
B11: February
B12: March
B13: April
B14: May
B15: June

Sheet Ewaste Pickups
C1: Brighton | D1: Baretta | E1: Huonville
B2: July | C2: 0 | D2: 0 | E2: 0
B3: August | C3: =120+348 -> 468 | E3: 1360
B4: September
B5: October
B6: November
B7: December
B8: January
B9: February
B10: March
B11: April
B12: May
B13: June

Sheet Monthly Return Crunching
C2: Enter data in green cells
C3: No touchy red cells, they get calculated automatically
C5: OWF (Salvage Down)
C6: Iron and steel | D6: Aluminium | E6: Other Non-Ferrous | F6: Mixed Metals | G6: Ewaste | H6: Lead Acid Batteries | I6: Timber | J6: Bricks | K6: Building and Demolition | L6: Whitegoods | M6: Paper and Cardboard | N6: Plastics | O6: Glass | P6: Mixed Materials
C7: 2922 | D7: 78 | E7: 572 | F7: 472 | G7: 1309 | H7: 752 | I7: 2666 | J7: 6554.5 | K7: 24 | L7: 0 | M7: 132.5 | N7: 470 | O7: 4 | P7: 4125
C9: MSW
C10: Iron and steel | D10: Aluminium | E10: Other non-ferrous | F10: Mixed metals | G10: Textiles | H10: Mattresses | I10: Timber | J10: Bricks | K10: Building and Demolition | L10: Paper and cardboard | M10: Plastics | N10: Glass | O10: Mixed materials | Q10: Ewaste
B11: Crates | C11: 256.35 | D11: 75.8 | E11: 0 | F11: 308.3 | G11: 3655.55 | H11: 0 | I11: 133.4 | J11: 0 | K11: 22 | L11: 2564.5 | M11: 692.2 | N11: 368.7 | O11: 4492.2
B12: Pallets | C12: 2682.9 | D12: 381.65 | E12: 440.5 | F12: 931.05 | G12: 1067.27 | H12: 191.9 | I12: 6132.01 | J12: 1599.6 | K12: 350.3 | L12: 46 | M12: 1663.36 | N12: 691.3 | O12: 4112.36
B13: Coll Tubs | C13: 17.9 | D13: 3.05 | E13: 0 | F13: 4.8 | G13: 5.8 | H13: 0 | I13: 9.45 | J13: 2.9 | K13: 0 | L13: 23.6 | M13: 0 | N13: 8 | O13: 427
B14: Pickup | C14: 223 | D14: 0 | E14: 0 | F14: 0 | G14: 92 | H14: 0 | I14: 568 | J14: 60 | K14: 350 | L14: 8 | M14: 73 | N14: 41 | O14: 135 | P14: 0 | Q14: =C32 -> 727.65 | R14: ELEC
C15: =SUM(C11:C14) -> 3180.15 | D15: =SUM(D11:D14) -> 460.5 | E15: =SUM(E11:E14) -> 440.5 | F15: =SUM(F11:F14) -> 1244.15 | G15: =SUM(G11:G14) -> 4820.62 | H15: =SUM(H11:H14) -> 191.9 | I15: =SUM(I11:I14) -> 6842.86 | J15: =SUM(J11:J14) -> 1662.5 | ... O15: =SUM(O11:O14) -> 9166.56 | Q15: =(I24-(G7*0.44))*0.2 -> 40.208 | R15: Ewaste exc steel - salvage exc steel
C16: =C15 -> 3180.15 | D16: =D15 -> 460.5 | E16: =E15 -> 440.5 | F16: =F15 -> 1244.15 | G16: =G15 -> 4820.62 | H16: =H15 -> 191.9 | I16: =I15 -> 6842.86 | J16: =J15 -> 1662.5 | ... N16: =N15 -> 1109 | O16: =(O15+D32)-(M20-M19)-(Q20-Q16) -> 13950.215 | P16: <- + ELEC
C18: RTL (Salvage Up) | M18: Ewaste C&I | Q18: Ewaste MSW | R18: MSW Inc steel
C19: Iron and steel | D19: Timber | E19: Textiles | F19: Plastics | G19: Paper and Cardboard | H19: Mattresses | I19: Ewaste | J19: Glass | K19: Mixed Materials | M19: =(I24-(G7*0.44))*0.8 -> 160.832 | N19: Exc steel | O19: 0.8 | Q19: =(Q14+(Q15/0.44)) -> 819.03182
C20: 1336 | D20: 1146 | E20: 1232 | F20: 1650 | G20: 338 | H20: 0 | I20: 956 | J20: 408 | K20: 8162 | M20: =M19/0.44 -> 365.52727 | N20: Inc steel
C22: Scrap
C23: Iron and steel | D23: Aluminium | E23: Other Non-Ferrous | F23: Mixed Metals | G23: Ewaste | I23: Net Ewaste | M23: Ewaste Carry Over | P23: Ewaste Pickups
C24: 0 | D24: 0 | E24: 0 | F24: 0 | G24: 1977 | I24: =G24-M24-(SUM(Q24:Q26)*0.44) -> 777 | L24: Previous Month | M24: 1200 | P24: Brighton | Q24: 0
L25: This Month | M25: 1500 | P25: Baretta | Q25: 0
C26: ELEC | P26: Huonville | Q26: 0
C27: Ewaste | D27: Mixed | F27: Whitegoods (count) | J27: whitegood weight
B28: Crates | C28: 232 | D28: 2464 | F28: 20 | J28: 48 | P28: TV Waste Disposal
B29: Pallets | C29: 495.65 | D29: 1564.35 | F29: =F28*J28 -> 960 | P29: Brighton
P30: Baretta
C31: Ewaste | D31: Mixed | P31: Huonville
B32: Total | C32: =C28+C29 -> 727.65 | D32: =D28+D29+F29 -> 4988.35
P33: How to separate these? Is it tracked?
C34: 5% of Elec is ewaste (tvs, monitors etc) | L34: Ewaste: 56% steel, 44% other
C35: Other 95% is mixed materials
L36: Carry over ewaste:
L37: Ewaste numbers for C&I and MSW can be negative if we have had a month where we salvaged and picked up a lot of ewaste but did not process it yet
L38: In thie situation we need to bring forward some processed ewaste from the next month so that these figures are not negative
L39: To do this, increase the ewaste number in cell G24 until the numbers in M19:20 and Q19 are positive
L40: Use cell M25 to make a note of how much you increased it by
L41: When clearing the green cells to input the next month's data, move the value from M25 to M24
L42: This will reduce the next month's ewaste figure so that the amount that was brought forward is not counted twice

Sheet MonthlyNRE
C2: In | D2: Out | F2: Copy Into Annual Return:
B3: Aluminium - salvaged - MSW | C3: ='Monthly Return Crunching'!D7/1000 -> 0.078 | D3: =C3 -> 0.078 | F3: Month: | G3: 3
B4: Aluminium - drop off - MSW | C4: ='Monthly Return Crunching'!D16/1000 -> 0.4605 | D4: =C4 -> 0.4605
B5: Bricks - salvaged -MSW | C5: ='Monthly Return Crunching'!J7/1000 -> 6.5545 | D5: =C5 -> 6.5545
B6: Bricks - drop off - MSW | C6: ='Monthly Return Crunching'!J16/1000 -> 1.6625 | D6: =C6 -> 1.6625
B7: Building and demolition material - salvaged - MSW | C7: ='Monthly Return Crunching'!K7/1000 -> 0.024 | D7: =C7 -> 0.024
B8: Building and demolition material - drop off - MSW | C8: ='Monthly Return Crunching'!K16/1000 -> 0.7223 | D8: =C8 -> 0.7223
B9: E-waste - salvaged - MSW | C9: ='Monthly Return Crunching'!G7/1000 -> 1.309 | D9: =(C9-(D34*(C9/(C9+C10+C11))))+SUM(C12:C14) -> 0.80714544 | G9: 1 | H9: July
B10: E-waste - drop off - MSW | C10: ='Monthly Return Crunching'!Q19/1000 -> 0.81903182 | D10: =('Monthly Return Crunching'!Q19/1000)-(D34*(C10/(C9+C10+C11))) -> 0.50502506 | G10: 2 | H10: August
B11: E-waste - drop off - C&I | C11: ='Monthly Return Crunching'!M20/1000 -> 0.36552727 | D11: =(C11-(D34*(C11/(C11+C10+C9)))) -> 0.2253886 | G11: 3 | H11: September
B12: E-waste - Salvaged - MSW - Brighton Council WTS | C12: ='Monthly Return Crunching'!Q24/1000 -> 0 | G12: 4 | H12: October
B13: E-waste - Salvaged - MSW - Baretta Waste & Recycling Centre | C13: ='Monthly Return Crunching'!Q25/1000 -> 0 | G13: 5 | H13: November
B14: E-waste - Salvaged - MSW - Southbridge WTS | C14: ='Monthly Return Crunching'!Q26/1000 -> 0 | G14: 6 | H14: December
B15: Glass - salvaged - MSW | C15: ='Monthly Return Crunching'!O7/1000 -> 0.004 | D15: =C15-(D40*(C15/(C15+C16))) -> 0.0025336927 | G15: 7 | H15: January
B16: Glass - drop off - MSW | C16: ='Monthly Return Crunching'!N16/1000 -> 1.109 | D16: =C16-(D40*(C16/(C16+C15))) -> 0.70246631 | G16: 8 | H16: February
